Workbook
Name SegmentaçãodeDados_STATUS: #N/A
Name SegmentaçãodeDados_TIPO: #N/A

Sheet RELATÓRIO
C2: =IF(E20="", IF(DAY(TODAY())>6, "RELATÓRIO FISCAL | "&F6&" "&G6, "RELATÓRIO FISCAL | "&F7&" "&G7 ), "RELATÓRIO FISCAL | "&UPPER(TEXT(E20,"mmmm"))&" "&TEXT(E20,"aaaa") ) -> RELATÓRIO FISCAL | AGOSTO 2026
C4: {=_xlfn.IFS( SEFAZ!I2="","", SEFAZ!I2="'19234190000300'","UNIDADE: PONTA NEGRA", SEFAZ!I2="'19234190000130'","UNIDADE: PARQUE DEZ", SEFAZ!I2="'19234190000725'","UNIDADE: MORADA DO SOL", SEFAZ!I2="'19234190000482'","UNIDADE: MONTE DAS OLIVEIRAS")}
B5: RECEBIDAS | D5: =COUNTIF(RELATORIO[STATUS],"RECEBIDA") -> 0
B6: NÃO LANÇADAS | D6: =COUNTIF(RELATORIO[STATUS],"NÃO LANÇADA") -> 0 | F6: =UPPER(TEXT(TODAY(),"mmmm")) -> SETEMBRO | G6: =TEXT(TODAY(),"aaaa") -> 2026
B7: CANCELADAS | D7: =COUNTIF(RELATORIO[STATUS],"CANCELADA") -> 0 | F7: =UPPER(TEXT(EDATE(TODAY(), -1),"mmmm")) -> AGOSTO | G7: =TEXT(EDATE(TODAY(),-1),"aaaa") -> 2026
B8: DEVOLUÇÕES | D8: =SUM(COUNTIF(RELATORIO[STATUS],"DEVOLUÇÃO"),COUNTIF(RELATORIO[STATUS],"DEVOLUÇÃO PARCIAL OU DEVOLUÇÃO DO MÊS ANTERIOR")) -> 0
B9: EM TRANSPORTE | D9: =COUNTIF(RELATORIO[STATUS],"EM TRANSPORTE") -> 0
B10: DESAGREGAÇÕES | D10: =COUNTIF(RELATORIO[STATUS],"DESAGREGAÇÃO") -> 0
B11: DESCARTE | D11: =COUNTIF(RELATORIO[STATUS],B11) -> 0
B12: REJEITADAS | D12: =COUNTIF(RELATORIO[STATUS],"REJEITADA") -> 0
B13: PARA REJEITAR | D13: =COUNTIF(RELATORIO[STATUS],"PARA REJEITAR") -> 0
B14: FALTA CHEGAR | D14: =COUNTIF(RELATORIO[STATUS],"FALTA CHEGAR") -> 0
B15: BAIXA DE ESTOQUE | D15: =COUNTIF(RELATORIO[STATUS],"SAÍDA DE ESTOQUE") -> 0
B16: TOTAL DE NOTAS | D16: =SUM(D5:D15) -> 0
B19: UF | C19: NF | D19: SERIE | E19: EMISSAO | F19: CNPJ EMISSOR | G19: FORNECEDOR | H19: CFOP | I19: SITUACAO | J19: TIPO | K19: VALOR | L19: STATUS | M19: JUSTIFICATIVA | N19: Observação | O19: CHAVE
B20: =IF(SEFAZ!A2="","",SEFAZ!A2) | C20: =IF(SEFAZ!C2="","",SEFAZ!C2) | D20: =IF(SEFAZ!D2="","",SEFAZ!D2) | E20: =IF(SEFAZ!E2="","",SEFAZ!E2) | F20: =IF(SEFAZ!F2="","",VALUE(SUBSTITUTE(SEFAZ!F2,"'",""))) | G20: =IF(SEFAZ!H2="","",SEFAZ!H2) | H20: =IF(SEFAZ!L2="","",SEFAZ!L2) | I20: =IF(SEFAZ!N2="","",SEFAZ!N2) | J20: =IF(SEFAZ!O2="","",SEFAZ!O2) | K20: =IF(SEFAZ!P2="","",SEFAZ!P2) | L20: {=IF(RELATORIO[[#This Row],[NF]] = "", "", IF(RELATORIO[[#This Row],[TIPO]] = "ENTRADA", VLOOKUP(RELATORIO[[#This Row],[NF]], TABELA_ENTRADAS[[#All], [NF]:[RELAÇÃO]], 10, FALSE), IFERROR( IF( _xlfn.XLOOKUP(1,(tabela_compras[NF]=RELATORIO[[#This Row],[NF]])*(ABS(tabela_compras[Vlr. Nota]-RELATORIO[[#This Row],[VALOR]])<=0.02),tabela_compras[NF]), "RECEBIDA" ), IF(RELATORIO[[#This Row],[SITUACAO]] = "CANCELADA", "CANCELADA", IF(SEFAZ!V2 = "S", "REJEITADA", IF(RELATORIO[[#This Row],[JUSTIFICATIVA]] <> "NÃO PRECISA", RELATORIO[[#This Row],[JUSTIFICATIVA]], IF(RELATORIO[[#This Row],[CFOP]] = 5926, "DESAGREGAÇÃO", IF(AND(RELATORIO[[#This Row],[CFOP]] = 5949, OR(RELATORIO[[#This Row],[CNPJ EMISSOR]] = 19234190000725, RELATORIO[[#This Row],[CNPJ EMISSOR]] = 19234190000130, RELATORIO[[#This Row],[CNPJ EMISSOR]] = 19234190000300, RELATORIO[[#This Row],[CNPJ EMISSOR]] = 19234190000482, RELATORIO[[#This Row],[CNPJ EMISSOR]] = 19234190000644)), "SAÍDA DE ESTOQUE", IFERROR( IF( VLOOKUP(RELATORIO[[#This Row],[VALOR]], TABELA_ENTRADAS[VALOR], 1, FALSE), "DEVOLUÇÃO" ), IF(RELATORIO[[#This Row],[CFOP]] = 5927, "DESCARTE", IF(RELATORIO[[#This Row],[UF]] <> "AM", "EM TRANSPORTE", IF(RELATORIO[[#This Row],[EMISSAO]] >= TODAY()-2, "FALTA CHEGAR", "NÃO LANÇADA" ) ) ) ) ) ) ) ) ) ) ) )} | M20: NÃO PRECISA | O20: =IF(SEFAZ!B2="","",SEFAZ!B2)
B21: =IF(SEFAZ!A3="","",SEFAZ!A3) | C21: =IF(SEFAZ!C3="","",SEFAZ!C3) | D21: =IF(SEFAZ!D3="","",SEFAZ!D3) | E21: =IF(SEFAZ!E3="","",SEFAZ!E3) | F21: =IF(SEFAZ!F3="","",VALUE(SUBSTITUTE(SEFAZ!F3,"'",""))) | G21: =IF(SEFAZ!H3="","",SEFAZ!H3) | H21: =IF(SEFAZ!L3="","",SEFAZ!L3) | I21: =IF(SEFAZ!N3="","",SEFAZ!N3) | J21: =IF(SEFAZ!O3="","",SEFAZ!O3) | K21: =IF(SEFAZ!P3="","",SEFAZ!P3) | L21: {=IF(RELATORIO[[#This Row],[NF]] = "", "", IF(RELATORIO[[#This Row],[TIPO]] = "ENTRADA", VLOOKUP(RELATORIO[[#This Row],[NF]], TABELA_ENTRADAS[[#All], [NF]:[RELAÇÃO]], 10, FALSE), IFERROR( IF( _xlfn.XLOOKUP(1,(tabela_compras[NF]=RELATORIO[[#This Row],[NF]])*(ABS(tabela_compras[Vlr. Nota]-RELATORIO[[#This Row],[VALOR]])<=0.02),tabela_compras[NF]), "RECEBIDA" ), IF(RELATORIO[[#This Row],[SITUACAO]] = "CANCELADA", "CANCELADA", IF(SEFAZ!V3 = "S", "REJEITADA", IF(RELATORIO[[#This Row],[JUSTIFICATIVA]] <> "NÃO PRECISA", RELATORIO[[#This Row],[JUSTIFICATIVA]], IF(RELATORIO[[#This Row],[CFOP]] = 5926, "DESAGREGAÇÃO", IF(AND(RELATORIO[[#This Row],[CFOP]] = 5949, OR(RELATORIO[[#This Row],[CNPJ EMISSOR]] = 19234190000725, RELATORIO[[#This Row],[CNPJ EMISSOR]] = 19234190000130, RELATORIO[[#This Row],[CNPJ EMISSOR]] = 19234190000300, RELATORIO[[#This Row],[CNPJ EMISSOR]] = 19234190000482, RELATORIO[[#This Row],[CNPJ EMISSOR]] = 19234190000644)), "SAÍDA DE ESTOQUE", IFERROR( IF( VLOOKUP(RELATORIO[[#This Row],[VALOR]], TABELA_ENTRADAS[VALOR], 1, FALSE), "DEVOLUÇÃO" ), IF(RELATORIO[[#This Row],[CFOP]] = 5927, "DESCARTE", IF(RELATORIO[[#This Row],[UF]] <> "AM", "EM TRANSPORTE", IF(RELATORIO[[#This Row],[EMISSAO]] >= TODAY()-2, "FALTA CHEGAR", "NÃO LANÇADA" ) ) ) ) ) ) ) ) ) ) ) )} | M21: NÃO PRECISA | O21: =IF(SEFAZ!B3="","",SEFAZ!B3)
B22: =IF(SEFAZ!A4="","",SEFAZ!A4) | C22: =IF(SEFAZ!C4="","",SEFAZ!C4) | D22: =IF(SEFAZ!D4="","",SEFAZ!D4) | E22: =IF(SEFAZ!E4="","",SEFAZ!E4) | F22: =IF(SEFAZ!F4="","",VALUE(SUBSTITUTE(SEFAZ!F4,"'",""))) | G22: =IF(SEFAZ!H4="","",SEFAZ!H4) | H22: =IF(SEFAZ!L4="","",SEFAZ!L4) | I22: =IF(SEFAZ!N4="","",SEFAZ!N4) | J22: =IF(SEFAZ!O4="","",SEFAZ!O4) | K22: =IF(SEFAZ!P4="","",SEFAZ!P4) | L22: {=IF(RELATORIO[[#This Row],[NF]] = "", "", IF(RELATORIO[[#This Row],[TIPO]] = "ENTRADA", VLOOKUP(RELATORIO[[#This Row],[NF]], TABELA_ENTRADAS[[#All], [NF]:[RELAÇÃO]], 10, FALSE), IFERROR( IF( _xlfn.XLOOKUP(1,(tabela_compras[NF]=RELATORIO[[#This Row],[NF]])*(ABS(tabela_compras[Vlr. Nota]-RELATORIO[[#This Row],[VALOR]])<=0.02),tabela_compras[NF]), "RECEBIDA" ), IF(RELATORIO[[#This Row],[SITUACAO]] = "CANCELADA", "CANCELADA", IF(SEFAZ!V4 = "S", "REJEITADA", IF(RELATORIO[[#This Row],[JUSTIFICATIVA]] <> "NÃO PRECISA", RELATORIO[[#This Row],[JUSTIFICATIVA]], IF(RELATORIO[[#This Row],[CFOP]] = 5926, "DESAGREGAÇÃO", IF(AND(RELATORIO[[#This Row],[CFOP]] = 5949, OR(RELATORIO[[#This Row],[CNPJ EMISSOR]] = 19234190000725, RELATORIO[[#This Row],[CNPJ EMISSOR]] = 19234190000130, RELATORIO[[#This Row],[CNPJ EMISSOR]] = 19234190000300, RELATORIO[[#This Row],[CNPJ EMISSOR]] = 19234190000482, RELATORIO[[#This Row],[CNPJ EMISSOR]] = 19234190000644)), "SAÍDA DE ESTOQUE", IFERROR( IF( VLOOKUP(RELATORIO[[#This Row],[VALOR]], TABELA_ENTRADAS[VALOR], 1, FALSE), "DEVOLUÇÃO" ), IF(RELATORIO[[#This Row],[CFOP]] = 5927, "DESCARTE", IF(RELATORIO[[#This Row],[UF]] <> "AM", "EM TRANSPORTE", IF(RELATORIO[[#This Row],[EMISSAO]] >= TODAY()-2, "FALTA CHEGAR", "NÃO LANÇADA" ) ) ) ) ) ) ) ) ) ) ) )} | M22: NÃO PRECISA | O22: =IF(SEFAZ!B4="","",SEFAZ!B4)
B23: =IF(SEFAZ!A5="","",SEFAZ!A5) | C23: =IF(SEFAZ!C5="","",SEFAZ!C5) | D23: =IF(SEFAZ!D5="","",SEFAZ!D5) | E23: =IF(SEFAZ!E5="","",SEFAZ!E5) | F23: =IF(SEFAZ!F5="","",VALUE(SUBSTITUTE(SEFAZ!F5,"'",""))) | G23: =IF(SEFAZ!H5="","",SEFAZ!H5) | H23: =IF(SEFAZ!L5="","",SEFAZ!L5) | I23: =IF(SEFAZ!N5="","",SEFAZ!N5) | J23: =IF(SEFAZ!O5="","",SEFAZ!O5) | K23: =IF(SEFAZ!P5="","",SEFAZ!P5) | L23: {=IF(RELATORIO[[#This Row],[NF]] = "", "", IF(RELATORIO[[#This Row],[TIPO]] = "ENTRADA", VLOOKUP(RELATORIO[[#This Row],[NF]], TABELA_ENTRADAS[[#All], [NF]:[RELAÇÃO]], 10, FALSE), IFERROR( IF( _xlfn.XLOOKUP(1,(tabela_compras[NF]=RELATORIO[[#This Row],[NF]])*(ABS(tabela_compras[Vlr. Nota]-RELATORIO[[#This Row],[VALOR]])<=0.02),tabela_compras[NF]), "RECEBIDA" ), IF(RELATORIO[[#This Row],[SITUACAO]] = "CANCELADA", "CANCELADA", IF(SEFAZ!V5 = "S", "REJEITADA", IF(RELATORIO[[#This Row],[JUSTIFICATIVA]] <> "NÃO PRECISA", RELATORIO[[#This Row],[JUSTIFICATIVA]], IF(RELATORIO[[#This Row],[CFOP]] = 5926, "DESAGREGAÇÃO", IF(AND(RELATORIO[[#This Row],[CFOP]] = 5949, OR(RELATORIO[[#This Row],[CNPJ EMISSOR]] = 19234190000725, RELATORIO[[#This Row],[CNPJ EMISSOR]] = 19234190000130, RELATORIO[[#This Row],[CNPJ EMISSOR]] = 19234190000300, RELATORIO[[#This Row],[CNPJ EMISSOR]] = 19234190000482, RELATORIO[[#This Row],[CNPJ EMISSOR]] = 19234190000644)), "SAÍDA DE ESTOQUE", IFERROR( IF( VLOOKUP(RELATORIO[[#This Row],[VALOR]], TABELA_ENTRADAS[VALOR], 1, FALSE), "DEVOLUÇÃO" ), IF(RELATORIO[[#This Row],[CFOP]] = 5927, "DESCARTE", IF(RELATORIO[[#This Row],[UF]] <> "AM", "EM TRANSPORTE", IF(RELATORIO[[#This Row],[EMISSAO]] >= TODAY()-2, "FALTA CHEGAR", "NÃO LANÇADA" ) ) ) ) ) ) ) ) ) ) ) )} | M23: NÃO PRECISA | O23: =IF(SEFAZ!B5="","",SEFAZ!B5)
B24: =IF(SEFAZ!A6="","",SEFAZ!A6) | C24: =IF(SEFAZ!C6="","",SEFAZ!C6) | D24: =IF(SEFAZ!D6="","",SEFAZ!D6) | E24: =IF(SEFAZ!E6="","",SEFAZ!E6) | F24: =IF(SEFAZ!F6="","",VALUE(SUBSTITUTE(SEFAZ!F6,"'",""))) | G24: =IF(SEFAZ!H6="","",SEFAZ!H6) | H24: =IF(SEFAZ!L6="","",SEFAZ!L6) | I24: =IF(SEFAZ!N6="","",SEFAZ!N6) | J24: =IF(SEFAZ!O6="","",SEFAZ!O6) | K24: =IF(SEFAZ!P6="","",SEFAZ!P6) | L24: {=IF(RELATORIO[[#This Row],[NF]] = "", "", IF(RELATORIO[[#This Row],[TIPO]] = "ENTRADA", VLOOKUP(RELATORIO[[#This Row],[NF]], TABELA_ENTRADAS[[#All], [NF]:[RELAÇÃO]], 10, FALSE), IFERROR( IF( _xlfn.XLOOKUP(1,(tabela_compras[NF]=RELATORIO[[#This Row],[NF]])*(ABS(tabela_compras[Vlr. Nota]-RELATORIO[[#This Row],[VALOR]])<=0.02),tabela_compras[NF]), "RECEBIDA" ), IF(RELATORIO[[#This Row],[SITUACAO]] = "CANCELADA", "CANCELADA", IF(SEFAZ!V6 = "S", "REJEITADA", IF(RELATORIO[[#This Row],[JUSTIFICATIVA]] <> "NÃO PRECISA", RELATORIO[[#This Row],[JUSTIFICATIVA]], IF(RELATORIO[[#This Row],[CFOP]] = 5926, "DESAGREGAÇÃO", IF(AND(RELATORIO[[#This Row],[CFOP]] = 5949, OR(RELATORIO[[#This Row],[CNPJ EMISSOR]] = 19234190000725, RELATORIO[[#This Row],[CNPJ EMISSOR]] = 19234190000130, RELATORIO[[#This Row],[CNPJ EMISSOR]] = 19234190000300, RELATORIO[[#This Row],[CNPJ EMISSOR]] = 19234190000482, RELATORIO[[#This Row],[CNPJ EMISSOR]] = 19234190000644)), "SAÍDA DE ESTOQUE", IFERROR( IF( VLOOKUP(RELATORIO[[#This Row],[VALOR]], TABELA_ENTRADAS[VALOR], 1, FALSE), "DEVOLUÇÃO" ), IF(RELATORIO[[#This Row],[CFOP]] = 5927, "DESCARTE", IF(RELATORIO[[#This Row],[UF]] <> "AM", "EM TRANSPORTE", IF(RELATORIO[[#This Row],[EMISSAO]] >= TODAY()-2, "FALTA CHEGAR", "NÃO LANÇADA" ) ) ) ) ) ) ) ) ) ) ) )} | M24: NÃO PRECISA | O24: =IF(SEFAZ!B6="","",SEFAZ!B6)
B25: =IF(SEFAZ!A7="","",SEFAZ!A7) | C25: =IF(SEFAZ!C7="","",SEFAZ!C7) | D25: =IF(SEFAZ!D7="","",SEFAZ!D7) | E25: =IF(SEFAZ!E7="","",SEFAZ!E7) | F25: =IF(SEFAZ!F7="","",VALUE(SUBSTITUTE(SEFAZ!F7,"'",""))) | G25: =IF(SEFAZ!H7="","",SEFAZ!H7) | H25: =IF(SEFAZ!L7="","",SEFAZ!L7) | I25: =IF(SEFAZ!N7="","",SEFAZ!N7) | J25: =IF(SEFAZ!O7="","",SEFAZ!O7) | K25: =IF(SEFAZ!P7="","",SEFAZ!P7) | L25: {=IF(RELATORIO[[#This Row],[NF]] = "", "", IF(RELATORIO[[#This Row],[TIPO]] = "ENTRADA", VLOOKUP(RELATORIO[[#This Row],[NF]], TABELA_ENTRADAS[[#All], [NF]:[RELAÇÃO]], 10, FALSE), IFERROR( IF( _xlfn.XLOOKUP(1,(tabela_compras[NF]=RELATORIO[[#This Row],[NF]])*(ABS(tabela_compras[Vlr. Nota]-RELATORIO[[#This Row],[VALOR]])<=0.02),tabela_compras[NF]), "RECEBIDA" ), IF(RELATORIO[[#This Row],[SITUACAO]] = "CANCELADA", "CANCELADA", IF(SEFAZ!V7 = "S", "REJEITADA", IF(RELATORIO[[#This Row],[JUSTIFICATIVA]] <> "NÃO PRECISA", RELATORIO[[#This Row],[JUSTIFICATIVA]], IF(RELATORIO[[#This Row],[CFOP]] = 5926, "DESAGREGAÇÃO", IF(AND(RELATORIO[[#This Row],[CFOP]] = 5949, OR(RELATORIO[[#This Row],[CNPJ EMISSOR]] = 19234190000725, RELATORIO[[#This Row],[CNPJ EMISSOR]] = 19234190000130, RELATORIO[[#This Row],[CNPJ EMISSOR]] = 19234190000300, RELATORIO[[#This Row],[CNPJ EMISSOR]] = 19234190000482, RELATORIO[[#This Row],[CNPJ EMISSOR]] = 19234190000644)), "SAÍDA DE ESTOQUE", IFERROR( IF( VLOOKUP(RELATORIO[[#This Row],[VALOR]], TABELA_ENTRADAS[VALOR], 1, FALSE), "DEVOLUÇÃO" ), IF(RELATORIO[[#This Row],[CFOP]] = 5927, "DESCARTE", IF(RELATORIO[[#This Row],[UF]] <> "AM", "EM TRANSPORTE", IF(RELATORIO[[#This Row],[EMISSAO]] >= TODAY()-2, "FALTA CHEGAR", "NÃO LANÇADA" ) ) ) ) ) ) ) ) ) ) ) )} | M25: NÃO PRECISA | O25: =IF(SEFAZ!B7="","",SEFAZ!B7)
B26: =IF(SEFAZ!A8="","",SEFAZ!A8) | C26: =IF(SEFAZ!C8="","",SEFAZ!C8) | D26: =IF(SEFAZ!D8="","",SEFAZ!D8) | E26: =IF(SEFAZ!E8="","",SEFAZ!E8) | F26: =IF(SEFAZ!F8="","",VALUE(SUBSTITUTE(SEFAZ!F8,"'",""))) | G26: =IF(SEFAZ!H8="","",SEFAZ!H8) | H26: =IF(SEFAZ!L8="","",SEFAZ!L8) | I26: =IF(SEFAZ!N8="","",SEFAZ!N8) | J26: =IF(SEFAZ!O8="","",SEFAZ!O8) | K26: =IF(SEFAZ!P8="","",SEFAZ!P8) | L26: {=IF(RELATORIO[[#This Row],[NF]] = "", "", IF(RELATORIO[[#This Row],[TIPO]] = "ENTRADA", VLOOKUP(RELATORIO[[#This Row],[NF]], TABELA_ENTRADAS[[#All], [NF]:[RELAÇÃO]], 10, FALSE), IFERROR( IF( _xlfn.XLOOKUP(1,(tabela_compras[NF]=RELATORIO[[#This Row],[NF]])*(ABS(tabela_compras[Vlr. Nota]-RELATORIO[[#This Row],[VALOR]])<=0.02),tabela_compras[NF]), "RECEBIDA" ), IF(RELATORIO[[#This Row],[SITUACAO]] = "CANCELADA", "CANCELADA", IF(SEFAZ!V8 = "S", "REJEITADA", IF(RELATORIO[[#This Row],[JUSTIFICATIVA]] <> "NÃO PRECISA", RELATORIO[[#This Row],[JUSTIFICATIVA]], IF(RELATORIO[[#This Row],[CFOP]] = 5926, "DESAGREGAÇÃO", IF(AND(RELATORIO[[#This Row],[CFOP]] = 5949, OR(RELATORIO[[#This Row],[CNPJ EMISSOR]] = 19234190000725, RELATORIO[[#This Row],[CNPJ EMISSOR]] = 19234190000130, RELATORIO[[#This Row],[CNPJ EMISSOR]] = 19234190000300, RELATORIO[[#This Row],[CNPJ EMISSOR]] = 19234190000482, RELATORIO[[#This Row],[CNPJ EMISSOR]] = 19234190000644)), "SAÍDA DE ESTOQUE", IFERROR( IF( VLOOKUP(RELATORIO[[#This Row],[VALOR]], TABELA_ENTRADAS[VALOR], 1, FALSE), "DEVOLUÇÃO" ), IF(RELATORIO[[#This Row],[CFOP]] = 5927, "DESCARTE", IF(RELATORIO[[#This Row],[UF]] <> "AM", "EM TRANSPORTE", IF(RELATORIO[[#This Row],[EMISSAO]] >= TODAY()-2, "FALTA CHEGAR", "NÃO LANÇADA" ) ) ) ) ) ) ) ) ) ) ) )} | M26: NÃO PRECISA | O26: =IF(SEFAZ!B8="","",SEFAZ!B8)
B27: =IF(SEFAZ!A9="","",SEFAZ!A9) | C27: =IF(SEFAZ!C9="","",SEFAZ!C9) | D27: =IF(SEFAZ!D9="","",SEFAZ!D9) | E27: =IF(SEFAZ!E9="","",SEFAZ!E9) | F27: =IF(SEFAZ!F9="","",VALUE(SUBSTITUTE(SEFAZ!F9,"'",""))) | G27: =IF(SEFAZ!H9="","",SEFAZ!H9) | H27: =IF(SEFAZ!L9="","",SEFAZ!L9) | I27: =IF(SEFAZ!N9="","",SEFAZ!N9) | J27: =IF(SEFAZ!O9="","",SEFAZ!O9) | K27: =IF(SEFAZ!P9="","",SEFAZ!P9) | L27: {=IF(RELATORIO[[#This Row],[NF]] = "", "", IF(RELATORIO[[#This Row],[TIPO]] = "ENTRADA", VLOOKUP(RELATORIO[[#This Row],[NF]], TABELA_ENTRADAS[[#All], [NF]:[RELAÇÃO]], 10, FALSE), IFERROR( IF( _xlfn.XLOOKUP(1,(tabela_compras[NF]=RELATORIO[[#This Row],[NF]])*(ABS(tabela_compras[Vlr. Nota]-RELATORIO[[#This Row],[VALOR]])<=0.02),tabela_compras[NF]), "RECEBIDA" ), IF(RELATORIO[[#This Row],[SITUACAO]] = "CANCELADA", "CANCELADA", IF(SEFAZ!V9 = "S", "REJEITADA", IF(RELATORIO[[#This Row],[JUSTIFICATIVA]] <> "NÃO PRECISA", RELATORIO[[#This Row],[JUSTIFICATIVA]], IF(RELATORIO[[#This Row],[CFOP]] = 5926, "DESAGREGAÇÃO", IF(AND(RELATORIO[[#This Row],[CFOP]] = 5949, OR(RELATORIO[[#This Row],[CNPJ EMISSOR]] = 19234190000725, RELATORIO[[#This Row],[CNPJ EMISSOR]] = 19234190000130, RELATORIO[[#This Row],[CNPJ EMISSOR]] = 19234190000300, RELATORIO[[#This Row],[CNPJ EMISSOR]] = 19234190000482, RELATORIO[[#This Row],[CNPJ EMISSOR]] = 19234190000644)), "SAÍDA DE ESTOQUE", IFERROR( IF( VLOOKUP(RELATORIO[[#This Row],[VALOR]], TABELA_ENTRADAS[VALOR], 1, FALSE), "DEVOLUÇÃO" ), IF(RELATORIO[[#This Row],[CFOP]] = 5927, "DESCARTE", IF(RELATORIO[[#This Row],[UF]] <> "AM", "EM TRANSPORTE", IF(RELATORIO[[#This Row],[EMISSAO]] >= TODAY()-2, "FALTA CHEGAR", "NÃO LANÇADA" ) ) ) ) ) ) ) ) ) ) ) )} | M27: NÃO PRECISA | O27: =IF(SEFAZ!B9="","",SEFAZ!B9)
B28: =IF(SEFAZ!A10="","",SEFAZ!A10) | C28: =IF(SEFAZ!C10="","",SEFAZ!C10) | D28: =IF(SEFAZ!D10="","",SEFAZ!D10) | E28: =IF(SEFAZ!E10="","",SEFAZ!E10) | F28: =IF(SEFAZ!F10="","",VALUE(SUBSTITUTE(SEFAZ!F10,"'",""))) | G28: =IF(SEFAZ!H10="","",SEFAZ!H10) | H28: =IF(SEFAZ!L10="","",SEFAZ!L10) | I28: =IF(SEFAZ!N10="","",SEFAZ!N10) | J28: =IF(SEFAZ!O10="","",SEFAZ!O10) | K28: =IF(SEFAZ!P10="","",SEFAZ!P10) | L28: {=IF(RELATORIO[[#This Row],[NF]] = "", "", IF(RELATORIO[[#This Row],[TIPO]] = "ENTRADA", VLOOKUP(RELATORIO[[#This Row],[NF]], TABELA_ENTRADAS[[#All], [NF]:[RELAÇÃO]], 10, FALSE), IFERROR( IF( _xlfn.XLOOKUP(1,(tabela_compras[NF]=RELATORIO[[#This Row],[NF]])*(ABS(tabela_compras[Vlr. Nota]-RELATORIO[[#This Row],[VALOR]])<=0.02),tabela_compras[NF]), "RECEBIDA" ), IF(RELATORIO[[#This Row],[SITUACAO]] = "CANCELADA", "CANCELADA", IF(SEFAZ!V10 = "S", "REJEITADA", IF(RELATORIO[[#This Row],[JUSTIFICATIVA]] <> "NÃO PRECISA", RELATORIO[[#This Row],[JUSTIFICATIVA]], IF(RELATORIO[[#This Row],[CFOP]] = 5926, "DESAGREGAÇÃO", IF(AND(RELATORIO[[#This Row],[CFOP]] = 5949, OR(RELATORIO[[#This Row],[CNPJ EMISSOR]] = 19234190000725, RELATORIO[[#This Row],[CNPJ EMISSOR]] = 19234190000130, RELATORIO[[#This Row],[CNPJ EMISSOR]] = 19234190000300, RELATORIO[[#This Row],[CNPJ EMISSOR]] = 19234190000482, RELATORIO[[#This Row],[CNPJ EMISSOR]] = 19234190000644)), "SAÍDA DE ESTOQUE", IFERROR( IF( VLOOKUP(RELATORIO[[#This Row],[VALOR]], TABELA_ENTRADAS[VALOR], 1, FALSE), "DEVOLUÇÃO" ), IF(RELATORIO[[#This Row],[CFOP]] = 5927, "DESCARTE", IF(RELATORIO[[#This Row],[UF]] <> "AM", "EM TRANSPORTE", IF(RELATORIO[[#This Row],[EMISSAO]] >= TODAY()-2, "FALTA CHEGAR", "NÃO LANÇADA" ) ) ) ) ) ) ) ) ) ) ) )} | M28: NÃO PRECISA | O28: =IF(SEFAZ!B10="","",SEFAZ!B10)
B29: =IF(SEFAZ!A11="","",SEFAZ!A11) | C29: =IF(SEFAZ!C11="","",SEFAZ!C11) | D29: =IF(SEFAZ!D11="","",SEFAZ!D11) | E29: =IF(SEFAZ!E11="","",SEFAZ!E11) | F29: =IF(SEFAZ!F11="","",VALUE(SUBSTITUTE(SEFAZ!F11,"'",""))) | G29: =IF(SEFAZ!H11="","",SEFAZ!H11) | H29: =IF(SEFAZ!L11="","",SEFAZ!L11) | I29: =IF(SEFAZ!N11="","",SEFAZ!N11) | J29: =IF(SEFAZ!O11="","",SEFAZ!O11) | K29: =IF(SEFAZ!P11="","",SEFAZ!P11) | L29: {=IF(RELATORIO[[#This Row],[NF]] = "", "", IF(RELATORIO[[#This Row],[TIPO]] = "ENTRADA", VLOOKUP(RELATORIO[[#This Row],[NF]], TABELA_ENTRADAS[[#All], [NF]:[RELAÇÃO]], 10, FALSE), IFERROR( IF( _xlfn.XLOOKUP(1,(tabela_compras[NF]=RELATORIO[[#This Row],[NF]])*(ABS(tabela_compras[Vlr. Nota]-RELATORIO[[#This Row],[VALOR]])<=0.02),tabela_compras[NF]), "RECEBIDA" ), IF(RELATORIO[[#This Row],[SITUACAO]] = "CANCELADA", "CANCELADA", IF(SEFAZ!V11 = "S", "REJEITADA", IF(RELATORIO[[#This Row],[JUSTIFICATIVA]] <> "NÃO PRECISA", RELATORIO[[#This Row],[JUSTIFICATIVA]], IF(RELATORIO[[#This Row],[CFOP]] = 5926, "DESAGREGAÇÃO", IF(AND(RELATORIO[[#This Row],[CFOP]] = 5949, OR(RELATORIO[[#This Row],[CNPJ EMISSOR]] = 19234190000725, RELATORIO[[#This Row],[CNPJ EMISSOR]] = 19234190000130, RELATORIO[[#This Row],[CNPJ EMISSOR]] = 19234190000300, RELATORIO[[#This Row],[CNPJ EMISSOR]] = 19234190000482, RELATORIO[[#This Row],[CNPJ EMISSOR]] = 19234190000644)), "SAÍDA DE ESTOQUE", IFERROR( IF( VLOOKUP(RELATORIO[[#This Row],[VALOR]], TABELA_ENTRADAS[VALOR], 1, FALSE), "DEVOLUÇÃO" ), IF(RELATORIO[[#This Row],[CFOP]] = 5927, "DESCARTE", IF(RELATORIO[[#This Row],[UF]] <> "AM", "EM TRANSPORTE", IF(RELATORIO[[#This Row],[EMISSAO]] >= TODAY()-2, "FALTA CHEGAR", "NÃO LANÇADA" ) ) ) ) ) ) ) ) ) ) ) )} | M29: NÃO PRECISA | O29: =IF(SEFAZ!B11="","",SEFAZ!B11)
B30: =IF(SEFAZ!A12="","",SEFAZ!A12) | C30: =IF(SEFAZ!C12="","",SEFAZ!C12) | D30: =IF(SEFAZ!D12="","",SEFAZ!D12) | E30: =IF(SEFAZ!E12="","",SEFAZ!E12) | F30: =IF(SEFAZ!F12="","",VALUE(SUBSTITUTE(SEFAZ!F12,"'",""))) | G30: =IF(SEFAZ!H12="","",SEFAZ!H12) | H30: =IF(SEFAZ!L12="","",SEFAZ!L12) | I30: =IF(SEFAZ!N12="","",SEFAZ!N12) | J30: =IF(SEFAZ!O12="","",SEFAZ!O12) | K30: =IF(SEFAZ!P12="","",SEFAZ!P12) | L30: {=IF(RELATORIO[[#This Row],[NF]] = "", "", IF(RELATORIO[[#This Row],[TIPO]] = "ENTRADA", VLOOKUP(RELATORIO[[#This Row],[NF]], TABELA_ENTRADAS[[#All], [NF]:[RELAÇÃO]], 10, FALSE), IFERROR( IF( _xlfn.XLOOKUP(1,(tabela_compras[NF]=RELATORIO[[#This Row],[NF]])*(ABS(tabela_compras[Vlr. Nota]-RELATORIO[[#This Row],[VALOR]])<=0.02),tabela_compras[NF]), "RECEBIDA" ), IF(RELATORIO[[#This Row],[SITUACAO]] = "CANCELADA", "CANCELADA", IF(SEFAZ!V12 = "S", "REJEITADA", IF(RELATORIO[[#This Row],[JUSTIFICATIVA]] <> "NÃO PRECISA", RELATORIO[[#This Row],[JUSTIFICATIVA]], IF(RELATORIO[[#This Row],[CFOP]] = 5926, "DESAGREGAÇÃO", IF(AND(RELATORIO[[#This Row],[CFOP]] = 5949, OR(RELATORIO[[#This Row],[CNPJ EMISSOR]] = 19234190000725, RELATORIO[[#This Row],[CNPJ EMISSOR]] = 19234190000130, RELATORIO[[#This Row],[CNPJ EMISSOR]] = 19234190000300, RELATORIO[[#This Row],[CNPJ EMISSOR]] = 19234190000482, RELATORIO[[#This Row],[CNPJ EMISSOR]] = 19234190000644)), "SAÍDA DE ESTOQUE", IFERROR( IF( VLOOKUP(RELATORIO[[#This Row],[VALOR]], TABELA_ENTRADAS[VALOR], 1, FALSE), "DEVOLUÇÃO" ), IF(RELATORIO[[#This Row],[CFOP]] = 5927, "DESCARTE", IF(RELATORIO[[#This Row],[UF]] <> "AM", "EM TRANSPORTE", IF(RELATORIO[[#This Row],[EMISSAO]] >= TODAY()-2, "FALTA CHEGAR", "NÃO LANÇADA" ) ) ) ) ) ) ) ) ) ) ) )} | M30: NÃO PRECISA | O30: =IF(SEFAZ!B12="","",SEFAZ!B12)
B31: =IF(SEFAZ!A13="","",SEFAZ!A13) | C31: =IF(SEFAZ!C13="","",SEFAZ!C13) | D31: =IF(SEFAZ!D13="","",SEFAZ!D13) | E31: =IF(SEFAZ!E13="","",SEFAZ!E13) | F31: =IF(SEFAZ!F13="","",VALUE(SUBSTITUTE(SEFAZ!F13,"'",""))) | G31: =IF(SEFAZ!H13="","",SEFAZ!H13) | H31: =IF(SEFAZ!L13="","",SEFAZ!L13) | I31: =IF(SEFAZ!N13="","",SEFAZ!N13) | J31: =IF(SEFAZ!O13="","",SEFAZ!O13) | K31: =IF(SEFAZ!P13="","",SEFAZ!P13) | L31: {=IF(RELATORIO[[#This Row],[NF]] = "", "", IF(RELATORIO[[#This Row],[TIPO]] = "ENTRADA", VLOOKUP(RELATORIO[[#This Row],[NF]], TABELA_ENTRADAS[[#All], [NF]:[RELAÇÃO]], 10, FALSE), IFERROR( IF( _xlfn.XLOOKUP(1,(tabela_compras[NF]=RELATORIO[[#This Row],[NF]])*(ABS(tabela_compras[Vlr. Nota]-RELATORIO[[#This Row],[VALOR]])<=0.02),tabela_compras[NF]), "RECEBIDA" ), IF(RELATORIO[[#This Row],[SITUACAO]] = "CANCELADA", "CANCELADA", IF(SEFAZ!V13 = "S", "REJEITADA", IF(RELATORIO[[#This Row],[JUSTIFICATIVA]] <> "NÃO PRECISA", RELATORIO[[#This Row],[JUSTIFICATIVA]], IF(RELATORIO[[#This Row],[CFOP]] = 5926, "DESAGREGAÇÃO", IF(AND(RELATORIO[[#This Row],[CFOP]] = 5949, OR(RELATORIO[[#This Row],[CNPJ EMISSOR]] = 19234190000725, RELATORIO[[#This Row],[CNPJ EMISSOR]] = 19234190000130, RELATORIO[[#This Row],[CNPJ EMISSOR]] = 19234190000300, RELATORIO[[#This Row],[CNPJ EMISSOR]] = 19234190000482, RELATORIO[[#This Row],[CNPJ EMISSOR]] = 19234190000644)), "SAÍDA DE ESTOQUE", IFERROR( IF( VLOOKUP(RELATORIO[[#This Row],[VALOR]], TABELA_ENTRADAS[VALOR], 1, FALSE), "DEVOLUÇÃO" ), IF(RELATORIO[[#This Row],[CFOP]] = 5927, "DESCARTE", IF(RELATORIO[[#This Row],[UF]] <> "AM", "EM TRANSPORTE", IF(RELATORIO[[#This Row],[EMISSAO]] >= TODAY()-2, "FALTA CHEGAR", "NÃO LANÇADA" ) ) ) ) ) ) ) ) ) ) ) )} | M31: NÃO PRECISA | O31: =IF(SEFAZ!B13="","",SEFAZ!B13)
... B1106: =IF(SEFAZ!A1088="","",SEFAZ!A1088) | C1106: =IF(SEFAZ!C1088="","",SEFAZ!C1088) | D1106: =IF(SEFAZ!D1088="","",SEFAZ!D1088) | E1106: =IF(SEFAZ!E1088="","",SEFAZ!E1088) | F1106: =IF(SEFAZ!F1088="","",VALUE(SUBSTITUTE(SEFAZ!F1088,"'",""))) | G1106: =IF(SEFAZ!H1088="","",SEFAZ!H1088) | H1106: =IF(SEFAZ!L1088="","",SEFAZ!L1088) | I1106: =IF(SEFAZ!N1088="","",SEFAZ!N1088) | J1106: =IF(SEFAZ!O1088="","",SEFAZ!O1088) | K1106: =IF(SEFAZ!P1088="","",SEFAZ!P1088) | L1106: {=IF(RELATORIO[[#This Row],[NF]] = "", "", IF(RELATORIO[[#This Row],[TIPO]] = "ENTRADA", VLOOKUP(RELATORIO[[#This Row],[NF]], TABELA_ENTRADAS[[#All], [NF]:[RELAÇÃO]], 10, FALSE), IFERROR( IF( _xlfn.XLOOKUP(1,(tabela_compras[NF]=RELATORIO[[#This Row],[NF]])*(ABS(tabela_compras[Vlr. Nota]-RELATORIO[[#This Row],[VALOR]])<=0.02),tabela_compras[NF]), "RECEBIDA" ), IF(RELATORIO[[#This Row],[SITUACAO]] = "CANCELADA", "CANCELADA", IF(SEFAZ!V1088 = "S", "REJEITADA", IF(RELATORIO[[#This Row],[JUSTIFICATIVA]] <> "NÃO PRECISA", RELATORIO[[#This Row],[JUSTIFICATIVA]], IF(RELATORIO[[#This Row],[CFOP]] = 5926, "DESAGREGAÇÃO", IF(AND(RELATORIO[[#This Row],[CFOP]] = 5949, OR(RELATORIO[[#This Row],[CNPJ EMISSOR]] = 19234190000725, RELATORIO[[#This Row],[CNPJ EMISSOR]] = 19234190000130, RELATORIO[[#This Row],[CNPJ EMISSOR]] = 19234190000300, RELATORIO[[#This Row],[CNPJ EMISSOR]] = 19234190000482, RELATORIO[[#This Row],[CNPJ EMISSOR]] = 19234190000644)), "SAÍDA DE ESTOQUE", IFERROR( IF( VLOOKUP(RELATORIO[[#This Row],[VALOR]], TABELA_ENTRADAS[VALOR], 1, FALSE), "DEVOLUÇÃO" ), IF(RELATORIO[[#This Row],[CFOP]] = 5927, "DESCARTE", IF(RELATORIO[[#This Row],[UF]] <> "AM", "EM TRANSPORTE", IF(RELATORIO[[#This Row],[EMISSAO]] >= TODAY()-2, "FALTA CHEGAR", "NÃO LANÇADA" ) ) ) ) ) ) ) ) ) ) ) )} | M1106: NÃO PRECISA | O1106: =IF(SEFAZ!B1088="","",SEFAZ!B1088)

Sheet ENTRADAS
B2: UF | C2: NF | D2: SERIE | E2: EMISSAO | F2: CNPJ EMISSOR | G2: FORNECEDOR | H2: CFOP | I2: SITUACAO | J2: TIPO | K2: VALOR | L2: RELAÇÃO
B3: =IF('ENTRADAS-BASE'!A1="","",'ENTRADAS-BASE'!A1) -> #VALUE! | C3: =IF('ENTRADAS-BASE'!B1="","",'ENTRADAS-BASE'!B1) | D3: =IF('ENTRADAS-BASE'!C1="","",'ENTRADAS-BASE'!C1) | E3: =IF('ENTRADAS-BASE'!D1="","",'ENTRADAS-BASE'!D1) | F3: =IF('ENTRADAS-BASE'!E1="","",'ENTRADAS-BASE'!E1) | G3: =IF('ENTRADAS-BASE'!F1="","",'ENTRADAS-BASE'!F1) | H3: =IF('ENTRADAS-BASE'!G1="","",'ENTRADAS-BASE'!G1) | I3: =IF('ENTRADAS-BASE'!H1="","",'ENTRADAS-BASE'!H1) | ... K3: =IF('ENTRADAS-BASE'!J1="","",'ENTRADAS-BASE'!J1) | L3: =IF(TABELA_ENTRADAS[[#This Row],[UF]]="","",IFERROR(IF(VLOOKUP(TABELA_ENTRADAS[[#This Row],[VALOR]],TABELA_SAIDAS[VALOR],1,FALSE),"DEVOLUÇÃO"),IF(TABELA_ENTRADAS[[#This Row],[SITUACAO]]="CANCELADA",TABELA_ENTRADAS[[#This Row],[SITUACAO]],IF(TABELA_ENTRADAS[[#This Row],[CFOP]]=1926,"DESAGREGAÇÃO","DEVOLUÇÃO PARCIAL OU DEVOLUÇÃO DO MÊS ANTERIOR")))) -> #VALUE!
B4: =IF('ENTRADAS-BASE'!A2="","",'ENTRADAS-BASE'!A2) | C4: =IF('ENTRADAS-BASE'!B2="","",'ENTRADAS-BASE'!B2) | D4: =IF('ENTRADAS-BASE'!C2="","",'ENTRADAS-BASE'!C2) | E4: =IF('ENTRADAS-BASE'!D2="","",'ENTRADAS-BASE'!D2) | F4: =IF('ENTRADAS-BASE'!E2="","",'ENTRADAS-BASE'!E2) | G4: =IF('ENTRADAS-BASE'!F2="","",'ENTRADAS-BASE'!F2) | H4: =IF('ENTRADAS-BASE'!G2="","",'ENTRADAS-BASE'!G2) | I4: =IF('ENTRADAS-BASE'!H2="","",'ENTRADAS-BASE'!H2) | ... K4: =IF('ENTRADAS-BASE'!J2="","",'ENTRADAS-BASE'!J2) | L4: =IF(TABELA_ENTRADAS[[#This Row],[UF]]="","",IFERROR(IF(VLOOKUP(TABELA_ENTRADAS[[#This Row],[VALOR]],TABELA_SAIDAS[VALOR],1,FALSE),"DEVOLUÇÃO"),IF(TABELA_ENTRADAS[[#This Row],[SITUACAO]]="CANCELADA",TABELA_ENTRADAS[[#This Row],[SITUACAO]],IF(TABELA_ENTRADAS[[#This Row],[CFOP]]=1926,"DESAGREGAÇÃO","DEVOLUÇÃO PARCIAL OU DEVOLUÇÃO DO MÊS ANTERIOR"))))
B5: =IF('ENTRADAS-BASE'!A3="","",'ENTRADAS-BASE'!A3) | C5: =IF('ENTRADAS-BASE'!B3="","",'ENTRADAS-BASE'!B3) | D5: =IF('ENTRADAS-BASE'!C3="","",'ENTRADAS-BASE'!C3) | E5: =IF('ENTRADAS-BASE'!D3="","",'ENTRADAS-BASE'!D3) | F5: =IF('ENTRADAS-BASE'!E3="","",'ENTRADAS-BASE'!E3) | G5: =IF('ENTRADAS-BASE'!F3="","",'ENTRADAS-BASE'!F3) | H5: =IF('ENTRADAS-BASE'!G3="","",'ENTRADAS-BASE'!G3) | I5: =IF('ENTRADAS-BASE'!H3="","",'ENTRADAS-BASE'!H3) | ... K5: =IF('ENTRADAS-BASE'!J3="","",'ENTRADAS-BASE'!J3) | L5: =IF(TABELA_ENTRADAS[[#This Row],[UF]]="","",IFERROR(IF(VLOOKUP(TABELA_ENTRADAS[[#This Row],[VALOR]],TABELA_SAIDAS[VALOR],1,FALSE),"DEVOLUÇÃO"),IF(TABELA_ENTRADAS[[#This Row],[SITUACAO]]="CANCELADA",TABELA_ENTRADAS[[#This Row],[SITUACAO]],IF(TABELA_ENTRADAS[[#This Row],[CFOP]]=1926,"DESAGREGAÇÃO","DEVOLUÇÃO PARCIAL OU DEVOLUÇÃO DO MÊS ANTERIOR"))))
B6: =IF('ENTRADAS-BASE'!A4="","",'ENTRADAS-BASE'!A4) | C6: =IF('ENTRADAS-BASE'!B4="","",'ENTRADAS-BASE'!B4) | D6: =IF('ENTRADAS-BASE'!C4="","",'ENTRADAS-BASE'!C4) | E6: =IF('ENTRADAS-BASE'!D4="","",'ENTRADAS-BASE'!D4) | F6: =IF('ENTRADAS-BASE'!E4="","",'ENTRADAS-BASE'!E4) | G6: =IF('ENTRADAS-BASE'!F4="","",'ENTRADAS-BASE'!F4) | H6: =IF('ENTRADAS-BASE'!G4="","",'ENTRADAS-BASE'!G4) | I6: =IF('ENTRADAS-BASE'!H4="","",'ENTRADAS-BASE'!H4) | ... K6: =IF('ENTRADAS-BASE'!J4="","",'ENTRADAS-BASE'!J4) | L6: =IF(TABELA_ENTRADAS[[#This Row],[UF]]="","",IFERROR(IF(VLOOKUP(TABELA_ENTRADAS[[#This Row],[VALOR]],TABELA_SAIDAS[VALOR],1,FALSE),"DEVOLUÇÃO"),IF(TABELA_ENTRADAS[[#This Row],[SITUACAO]]="CANCELADA",TABELA_ENTRADAS[[#This Row],[SITUACAO]],IF(TABELA_ENTRADAS[[#This Row],[CFOP]]=1926,"DESAGREGAÇÃO","DEVOLUÇÃO PARCIAL OU DEVOLUÇÃO DO MÊS ANTERIOR"))))
B7: =IF('ENTRADAS-BASE'!A5="","",'ENTRADAS-BASE'!A5) | C7: =IF('ENTRADAS-BASE'!B5="","",'ENTRADAS-BASE'!B5) | D7: =IF('ENTRADAS-BASE'!C5="","",'ENTRADAS-BASE'!C5) | E7: =IF('ENTRADAS-BASE'!D5="","",'ENTRADAS-BASE'!D5) | F7: =IF('ENTRADAS-BASE'!E5="","",'ENTRADAS-BASE'!E5) | G7: =IF('ENTRADAS-BASE'!F5="","",'ENTRADAS-BASE'!F5) | H7: =IF('ENTRADAS-BASE'!G5="","",'ENTRADAS-BASE'!G5) | I7: =IF('ENTRADAS-BASE'!H5="","",'ENTRADAS-BASE'!H5) | ... K7: =IF('ENTRADAS-BASE'!J5="","",'ENTRADAS-BASE'!J5) | L7: =IF(TABELA_ENTRADAS[[#This Row],[UF]]="","",IFERROR(IF(VLOOKUP(TABELA_ENTRADAS[[#This Row],[VALOR]],TABELA_SAIDAS[VALOR],1,FALSE),"DEVOLUÇÃO"),IF(TABELA_ENTRADAS[[#This Row],[SITUACAO]]="CANCELADA",TABELA_ENTRADAS[[#This Row],[SITUACAO]],IF(TABELA_ENTRADAS[[#This Row],[CFOP]]=1926,"DESAGREGAÇÃO","DEVOLUÇÃO PARCIAL OU DEVOLUÇÃO DO MÊS ANTERIOR"))))
B8: =IF('ENTRADAS-BASE'!A6="","",'ENTRADAS-BASE'!A6) | C8: =IF('ENTRADAS-BASE'!B6="","",'ENTRADAS-BASE'!B6) | D8: =IF('ENTRADAS-BASE'!C6="","",'ENTRADAS-BASE'!C6) | E8: =IF('ENTRADAS-BASE'!D6="","",'ENTRADAS-BASE'!D6) | F8: =IF('ENTRADAS-BASE'!E6="","",'ENTRADAS-BASE'!E6) | G8: =IF('ENTRADAS-BASE'!F6="","",'ENTRADAS-BASE'!F6) | H8: =IF('ENTRADAS-BASE'!G6="","",'ENTRADAS-BASE'!G6) | I8: =IF('ENTRADAS-BASE'!H6="","",'ENTRADAS-BASE'!H6) | ... K8: =IF('ENTRADAS-BASE'!J6="","",'ENTRADAS-BASE'!J6) | L8: =IF(TABELA_ENTRADAS[[#This Row],[UF]]="","",IFERROR(IF(VLOOKUP(TABELA_ENTRADAS[[#This Row],[VALOR]],TABELA_SAIDAS[VALOR],1,FALSE),"DEVOLUÇÃO"),IF(TABELA_ENTRADAS[[#This Row],[SITUACAO]]="CANCELADA",TABELA_ENTRADAS[[#This Row],[SITUACAO]],IF(TABELA_ENTRADAS[[#This Row],[CFOP]]=1926,"DESAGREGAÇÃO","DEVOLUÇÃO PARCIAL OU DEVOLUÇÃO DO MÊS ANTERIOR"))))
B9: =IF('ENTRADAS-BASE'!A7="","",'ENTRADAS-BASE'!A7) | C9: =IF('ENTRADAS-BASE'!B7="","",'ENTRADAS-BASE'!B7) | D9: =IF('ENTRADAS-BASE'!C7="","",'ENTRADAS-BASE'!C7) | E9: =IF('ENTRADAS-BASE'!D7="","",'ENTRADAS-BASE'!D7) | F9: =IF('ENTRADAS-BASE'!E7="","",'ENTRADAS-BASE'!E7) | G9: =IF('ENTRADAS-BASE'!F7="","",'ENTRADAS-BASE'!F7) | H9: =IF('ENTRADAS-BASE'!G7="","",'ENTRADAS-BASE'!G7) | I9: =IF('ENTRADAS-BASE'!H7="","",'ENTRADAS-BASE'!H7) | ... K9: =IF('ENTRADAS-BASE'!J7="","",'ENTRADAS-BASE'!J7) | L9: =IF(TABELA_ENTRADAS[[#This Row],[UF]]="","",IFERROR(IF(VLOOKUP(TABELA_ENTRADAS[[#This Row],[VALOR]],TABELA_SAIDAS[VALOR],1,FALSE),"DEVOLUÇÃO"),IF(TABELA_ENTRADAS[[#This Row],[SITUACAO]]="CANCELADA",TABELA_ENTRADAS[[#This Row],[SITUACAO]],IF(TABELA_ENTRADAS[[#This Row],[CFOP]]=1926,"DESAGREGAÇÃO","DEVOLUÇÃO PARCIAL OU DEVOLUÇÃO DO MÊS ANTERIOR"))))
B10: =IF('ENTRADAS-BASE'!A8="","",'ENTRADAS-BASE'!A8) | C10: =IF('ENTRADAS-BASE'!B8="","",'ENTRADAS-BASE'!B8) | D10: =IF('ENTRADAS-BASE'!C8="","",'ENTRADAS-BASE'!C8) | E10: =IF('ENTRADAS-BASE'!D8="","",'ENTRADAS-BASE'!D8) | F10: =IF('ENTRADAS-BASE'!E8="","",'ENTRADAS-BASE'!E8) | G10: =IF('ENTRADAS-BASE'!F8="","",'ENTRADAS-BASE'!F8) | H10: =IF('ENTRADAS-BASE'!G8="","",'ENTRADAS-BASE'!G8) | I10: =IF('ENTRADAS-BASE'!H8="","",'ENTRADAS-BASE'!H8) | ... K10: =IF('ENTRADAS-BASE'!J8="","",'ENTRADAS-BASE'!J8) | L10: =IF(TABELA_ENTRADAS[[#This Row],[UF]]="","",IFERROR(IF(VLOOKUP(TABELA_ENTRADAS[[#This Row],[VALOR]],TABELA_SAIDAS[VALOR],1,FALSE),"DEVOLUÇÃO"),IF(TABELA_ENTRADAS[[#This Row],[SITUACAO]]="CANCELADA",TABELA_ENTRADAS[[#This Row],[SITUACAO]],IF(TABELA_ENTRADAS[[#This Row],[CFOP]]=1926,"DESAGREGAÇÃO","DEVOLUÇÃO PARCIAL OU DEVOLUÇÃO DO MÊS ANTERIOR"))))
B11: =IF('ENTRADAS-BASE'!A9="","",'ENTRADAS-BASE'!A9) | C11: =IF('ENTRADAS-BASE'!B9="","",'ENTRADAS-BASE'!B9) | D11: =IF('ENTRADAS-BASE'!C9="","",'ENTRADAS-BASE'!C9) | E11: =IF('ENTRADAS-BASE'!D9="","",'ENTRADAS-BASE'!D9) | F11: =IF('ENTRADAS-BASE'!E9="","",'ENTRADAS-BASE'!E9) | G11: =IF('ENTRADAS-BASE'!F9="","",'ENTRADAS-BASE'!F9) | H11: =IF('ENTRADAS-BASE'!G9="","",'ENTRADAS-BASE'!G9) | I11: =IF('ENTRADAS-BASE'!H9="","",'ENTRADAS-BASE'!H9) | ... K11: =IF('ENTRADAS-BASE'!J9="","",'ENTRADAS-BASE'!J9) | L11: =IF(TABELA_ENTRADAS[[#This Row],[UF]]="","",IFERROR(IF(VLOOKUP(TABELA_ENTRADAS[[#This Row],[VALOR]],TABELA_SAIDAS[VALOR],1,FALSE),"DEVOLUÇÃO"),IF(TABELA_ENTRADAS[[#This Row],[SITUACAO]]="CANCELADA",TABELA_ENTRADAS[[#This Row],[SITUACAO]],IF(TABELA_ENTRADAS[[#This Row],[CFOP]]=1926,"DESAGREGAÇÃO","DEVOLUÇÃO PARCIAL OU DEVOLUÇÃO DO MÊS ANTERIOR"))))
B12: =IF('ENTRADAS-BASE'!A10="","",'ENTRADAS-BASE'!A10) | C12: =IF('ENTRADAS-BASE'!B10="","",'ENTRADAS-BASE'!B10) | D12: =IF('ENTRADAS-BASE'!C10="","",'ENTRADAS-BASE'!C10) | E12: =IF('ENTRADAS-BASE'!D10="","",'ENTRADAS-BASE'!D10) | F12: =IF('ENTRADAS-BASE'!E10="","",'ENTRADAS-BASE'!E10) | G12: =IF('ENTRADAS-BASE'!F10="","",'ENTRADAS-BASE'!F10) | H12: =IF('ENTRADAS-BASE'!G10="","",'ENTRADAS-BASE'!G10) | I12: =IF('ENTRADAS-BASE'!H10="","",'ENTRADAS-BASE'!H10) | ... K12: =IF('ENTRADAS-BASE'!J10="","",'ENTRADAS-BASE'!J10) | L12: =IF(TABELA_ENTRADAS[[#This Row],[UF]]="","",IFERROR(IF(VLOOKUP(TABELA_ENTRADAS[[#This Row],[VALOR]],TABELA_SAIDAS[VALOR],1,FALSE),"DEVOLUÇÃO"),IF(TABELA_ENTRADAS[[#This Row],[SITUACAO]]="CANCELADA",TABELA_ENTRADAS[[#This Row],[SITUACAO]],IF(TABELA_ENTRADAS[[#This Row],[CFOP]]=1926,"DESAGREGAÇÃO","DEVOLUÇÃO PARCIAL OU DEVOLUÇÃO DO MÊS ANTERIOR"))))
B13: =IF('ENTRADAS-BASE'!A11="","",'ENTRADAS-BASE'!A11) | C13: =IF('ENTRADAS-BASE'!B11="","",'ENTRADAS-BASE'!B11) | D13: =IF('ENTRADAS-BASE'!C11="","",'ENTRADAS-BASE'!C11) | E13: =IF('ENTRADAS-BASE'!D11="","",'ENTRADAS-BASE'!D11) | F13: =IF('ENTRADAS-BASE'!E11="","",'ENTRADAS-BASE'!E11) | G13: =IF('ENTRADAS-BASE'!F11="","",'ENTRADAS-BASE'!F11) | H13: =IF('ENTRADAS-BASE'!G11="","",'ENTRADAS-BASE'!G11) | I13: =IF('ENTRADAS-BASE'!H11="","",'ENTRADAS-BASE'!H11) | ... K13: =IF('ENTRADAS-BASE'!J11="","",'ENTRADAS-BASE'!J11) | L13: =IF(TABELA_ENTRADAS[[#This Row],[UF]]="","",IFERROR(IF(VLOOKUP(TABELA_ENTRADAS[[#This Row],[VALOR]],TABELA_SAIDAS[VALOR],1,FALSE),"DEVOLUÇÃO"),IF(TABELA_ENTRADAS[[#This Row],[SITUACAO]]="CANCELADA",TABELA_ENTRADAS[[#This Row],[SITUACAO]],IF(TABELA_ENTRADAS[[#This Row],[CFOP]]=1926,"DESAGREGAÇÃO","DEVOLUÇÃO PARCIAL OU DEVOLUÇÃO DO MÊS ANTERIOR"))))
B14: =IF('ENTRADAS-BASE'!A12="","",'ENTRADAS-BASE'!A12) | C14: =IF('ENTRADAS-BASE'!B12="","",'ENTRADAS-BASE'!B12) | D14: =IF('ENTRADAS-BASE'!C12="","",'ENTRADAS-BASE'!C12) | E14: =IF('ENTRADAS-BASE'!D12="","",'ENTRADAS-BASE'!D12) | F14: =IF('ENTRADAS-BASE'!E12="","",'ENTRADAS-BASE'!E12) | G14: =IF('ENTRADAS-BASE'!F12="","",'ENTRADAS-BASE'!F12) | H14: =IF('ENTRADAS-BASE'!G12="","",'ENTRADAS-BASE'!G12) | I14: =IF('ENTRADAS-BASE'!H12="","",'ENTRADAS-BASE'!H12) | ... K14: =IF('ENTRADAS-BASE'!J12="","",'ENTRADAS-BASE'!J12) | L14: =IF(TABELA_ENTRADAS[[#This Row],[UF]]="","",IFERROR(IF(VLOOKUP(TABELA_ENTRADAS[[#This Row],[VALOR]],TABELA_SAIDAS[VALOR],1,FALSE),"DEVOLUÇÃO"),IF(TABELA_ENTRADAS[[#This Row],[SITUACAO]]="CANCELADA",TABELA_ENTRADAS[[#This Row],[SITUACAO]],IF(TABELA_ENTRADAS[[#This Row],[CFOP]]=1926,"DESAGREGAÇÃO","DEVOLUÇÃO PARCIAL OU DEVOLUÇÃO DO MÊS ANTERIOR"))))
... B1000: =IF('ENTRADAS-BASE'!A998="","",'ENTRADAS-BASE'!A998) | C1000: =IF('ENTRADAS-BASE'!B998="","",'ENTRADAS-BASE'!B998) | D1000: =IF('ENTRADAS-BASE'!C998="","",'ENTRADAS-BASE'!C998) | E1000: =IF('ENTRADAS-BASE'!D998="","",'ENTRADAS-BASE'!D998) | F1000: =IF('ENTRADAS-BASE'!E998="","",'ENTRADAS-BASE'!E998) | G1000: =IF('ENTRADAS-BASE'!F998="","",'ENTRADAS-BASE'!F998) | H1000: =IF('ENTRADAS-BASE'!G998="","",'ENTRADAS-BASE'!G998) | I1000: =IF('ENTRADAS-BASE'!H998="","",'ENTRADAS-BASE'!H998) | ... K1000: =IF('ENTRADAS-BASE'!J998="","",'ENTRADAS-BASE'!J998) | L1000: =IF(TABELA_ENTRADAS[[#This Row],[UF]]="","",IFERROR(IF(VLOOKUP(TABELA_ENTRADAS[[#This Row],[VALOR]],TABELA_SAIDAS[VALOR],1,FALSE),"DEVOLUÇÃO"),IF(TABELA_ENTRADAS[[#This Row],[SITUACAO]]="CANCELADA",TABELA_ENTRADAS[[#This Row],[SITUACAO]],IF(TABELA_ENTRADAS[[#This Row],[CFOP]]=1926,"DESAGREGAÇÃO","DEVOLUÇÃO PARCIAL OU DEVOLUÇÃO DO MÊS ANTERIOR"))))

Sheet ENTRADAS-BASE
A1: {=_xlfn._xlws.FILTER(RELATORIO[[UF]:[VALOR]],RELATORIO[TIPO]="ENTRADA")} -> #VALUE!

Sheet SAÍDAS
B2: UF | C2: NF | D2: SERIE | E2: EMISSAO | F2: CNPJ EMISSOR | G2: FORNECEDOR | H2: CFOP | I2: SITUACAO | J2: TIPO | K2: VALOR | L2: RELAÇÃO
B3: =IF('SAÍDAS-BASE'!A1="","",'SAÍDAS-BASE'!A1) -> #VALUE! | C3: =IF('SAÍDAS-BASE'!B1="","",'SAÍDAS-BASE'!B1) | D3: =IF('SAÍDAS-BASE'!C1="","",'SAÍDAS-BASE'!C1) | E3: =IF('SAÍDAS-BASE'!D1="","",'SAÍDAS-BASE'!D1) | F3: =IF('SAÍDAS-BASE'!E1="","",'SAÍDAS-BASE'!E1) | G3: =IF('SAÍDAS-BASE'!F1="","",'SAÍDAS-BASE'!F1) | H3: =IF('SAÍDAS-BASE'!G1="","",'SAÍDAS-BASE'!G1) | I3: =IF('SAÍDAS-BASE'!H1="","",'SAÍDAS-BASE'!H1) | ... K3: =IF('SAÍDAS-BASE'!J1="","",'SAÍDAS-BASE'!J1) | L3: =IF(TABELA_SAIDAS[[#This Row],[UF]]="","",IFERROR(IF(VLOOKUP(TABELA_SAIDAS[[#This Row],[VALOR]],TABELA_ENTRADAS[VALOR],1,FALSE),"DEVOLUÇÃO"),"SEM ENTRADAS")) -> #VALUE!
B4: =IF('SAÍDAS-BASE'!A2="","",'SAÍDAS-BASE'!A2) | C4: =IF('SAÍDAS-BASE'!B2="","",'SAÍDAS-BASE'!B2) | D4: =IF('SAÍDAS-BASE'!C2="","",'SAÍDAS-BASE'!C2) | E4: =IF('SAÍDAS-BASE'!D2="","",'SAÍDAS-BASE'!D2) | F4: =IF('SAÍDAS-BASE'!E2="","",'SAÍDAS-BASE'!E2) | G4: =IF('SAÍDAS-BASE'!F2="","",'SAÍDAS-BASE'!F2) | H4: =IF('SAÍDAS-BASE'!G2="","",'SAÍDAS-BASE'!G2) | I4: =IF('SAÍDAS-BASE'!H2="","",'SAÍDAS-BASE'!H2) | ... K4: =IF('SAÍDAS-BASE'!J2="","",'SAÍDAS-BASE'!J2) | L4: =IF(TABELA_SAIDAS[[#This Row],[UF]]="","",IFERROR(IF(VLOOKUP(TABELA_SAIDAS[[#This Row],[VALOR]],TABELA_ENTRADAS[VALOR],1,FALSE),"DEVOLUÇÃO"),"SEM ENTRADAS"))
B5: =IF('SAÍDAS-BASE'!A3="","",'SAÍDAS-BASE'!A3) | C5: =IF('SAÍDAS-BASE'!B3="","",'SAÍDAS-BASE'!B3) | D5: =IF('SAÍDAS-BASE'!C3="","",'SAÍDAS-BASE'!C3) | E5: =IF('SAÍDAS-BASE'!D3="","",'SAÍDAS-BASE'!D3) | F5: =IF('SAÍDAS-BASE'!E3="","",'SAÍDAS-BASE'!E3) | G5: =IF('SAÍDAS-BASE'!F3="","",'SAÍDAS-BASE'!F3) | H5: =IF('SAÍDAS-BASE'!G3="","",'SAÍDAS-BASE'!G3) | I5: =IF('SAÍDAS-BASE'!H3="","",'SAÍDAS-BASE'!H3) | ... K5: =IF('SAÍDAS-BASE'!J3="","",'SAÍDAS-BASE'!J3) | L5: =IF(TABELA_SAIDAS[[#This Row],[UF]]="","",IFERROR(IF(VLOOKUP(TABELA_SAIDAS[[#This Row],[VALOR]],TABELA_ENTRADAS[VALOR],1,FALSE),"DEVOLUÇÃO"),"SEM ENTRADAS"))
B6: =IF('SAÍDAS-BASE'!A4="","",'SAÍDAS-BASE'!A4) | C6: =IF('SAÍDAS-BASE'!B4="","",'SAÍDAS-BASE'!B4) | D6: =IF('SAÍDAS-BASE'!C4="","",'SAÍDAS-BASE'!C4) | E6: =IF('SAÍDAS-BASE'!D4="","",'SAÍDAS-BASE'!D4) | F6: =IF('SAÍDAS-BASE'!E4="","",'SAÍDAS-BASE'!E4) | G6: =IF('SAÍDAS-BASE'!F4="","",'SAÍDAS-BASE'!F4) | H6: =IF('SAÍDAS-BASE'!G4="","",'SAÍDAS-BASE'!G4) | I6: =IF('SAÍDAS-BASE'!H4="","",'SAÍDAS-BASE'!H4) | ... K6: =IF('SAÍDAS-BASE'!J4="","",'SAÍDAS-BASE'!J4) | L6: =IF(TABELA_SAIDAS[[#This Row],[UF]]="","",IFERROR(IF(VLOOKUP(TABELA_SAIDAS[[#This Row],[VALOR]],TABELA_ENTRADAS[VALOR],1,FALSE),"DEVOLUÇÃO"),"SEM ENTRADAS"))
B7: =IF('SAÍDAS-BASE'!A5="","",'SAÍDAS-BASE'!A5) | C7: =IF('SAÍDAS-BASE'!B5="","",'SAÍDAS-BASE'!B5) | D7: =IF('SAÍDAS-BASE'!C5="","",'SAÍDAS-BASE'!C5) | E7: =IF('SAÍDAS-BASE'!D5="","",'SAÍDAS-BASE'!D5) | F7: =IF('SAÍDAS-BASE'!E5="","",'SAÍDAS-BASE'!E5) | G7: =IF('SAÍDAS-BASE'!F5="","",'SAÍDAS-BASE'!F5) | H7: =IF('SAÍDAS-BASE'!G5="","",'SAÍDAS-BASE'!G5) | I7: =IF('SAÍDAS-BASE'!H5="","",'SAÍDAS-BASE'!H5) | ... K7: =IF('SAÍDAS-BASE'!J5="","",'SAÍDAS-BASE'!J5) | L7: =IF(TABELA_SAIDAS[[#This Row],[UF]]="","",IFERROR(IF(VLOOKUP(TABELA_SAIDAS[[#This Row],[VALOR]],TABELA_ENTRADAS[VALOR],1,FALSE),"DEVOLUÇÃO"),"SEM ENTRADAS"))
B8: =IF('SAÍDAS-BASE'!A6="","",'SAÍDAS-BASE'!A6) | C8: =IF('SAÍDAS-BASE'!B6="","",'SAÍDAS-BASE'!B6) | D8: =IF('SAÍDAS-BASE'!C6="","",'SAÍDAS-BASE'!C6) | E8: =IF('SAÍDAS-BASE'!D6="","",'SAÍDAS-BASE'!D6) | F8: =IF('SAÍDAS-BASE'!E6="","",'SAÍDAS-BASE'!E6) | G8: =IF('SAÍDAS-BASE'!F6="","",'SAÍDAS-BASE'!F6) | H8: =IF('SAÍDAS-BASE'!G6="","",'SAÍDAS-BASE'!G6) | I8: =IF('SAÍDAS-BASE'!H6="","",'SAÍDAS-BASE'!H6) | ... K8: =IF('SAÍDAS-BASE'!J6="","",'SAÍDAS-BASE'!J6) | L8: =IF(TABELA_SAIDAS[[#This Row],[UF]]="","",IFERROR(IF(VLOOKUP(TABELA_SAIDAS[[#This Row],[VALOR]],TABELA_ENTRADAS[VALOR],1,FALSE),"DEVOLUÇÃO"),"SEM ENTRADAS"))
B9: =IF('SAÍDAS-BASE'!A7="","",'SAÍDAS-BASE'!A7) | C9: =IF('SAÍDAS-BASE'!B7="","",'SAÍDAS-BASE'!B7) | D9: =IF('SAÍDAS-BASE'!C7="","",'SAÍDAS-BASE'!C7) | E9: =IF('SAÍDAS-BASE'!D7="","",'SAÍDAS-BASE'!D7) | F9: =IF('SAÍDAS-BASE'!E7="","",'SAÍDAS-BASE'!E7) | G9: =IF('SAÍDAS-BASE'!F7="","",'SAÍDAS-BASE'!F7) | H9: =IF('SAÍDAS-BASE'!G7="","",'SAÍDAS-BASE'!G7) | I9: =IF('SAÍDAS-BASE'!H7="","",'SAÍDAS-BASE'!H7) | ... K9: =IF('SAÍDAS-BASE'!J7="","",'SAÍDAS-BASE'!J7) | L9: =IF(TABELA_SAIDAS[[#This Row],[UF]]="","",IFERROR(IF(VLOOKUP(TABELA_SAIDAS[[#This Row],[VALOR]],TABELA_ENTRADAS[VALOR],1,FALSE),"DEVOLUÇÃO"),"SEM ENTRADAS"))
B10: =IF('SAÍDAS-BASE'!A8="","",'SAÍDAS-BASE'!A8) | C10: =IF('SAÍDAS-BASE'!B8="","",'SAÍDAS-BASE'!B8) | D10: =IF('SAÍDAS-BASE'!C8="","",'SAÍDAS-BASE'!C8) | E10: =IF('SAÍDAS-BASE'!D8="","",'SAÍDAS-BASE'!D8) | F10: =IF('SAÍDAS-BASE'!E8="","",'SAÍDAS-BASE'!E8) | G10: =IF('SAÍDAS-BASE'!F8="","",'SAÍDAS-BASE'!F8) | H10: =IF('SAÍDAS-BASE'!G8="","",'SAÍDAS-BASE'!G8) | I10: =IF('SAÍDAS-BASE'!H8="","",'SAÍDAS-BASE'!H8) | ... K10: =IF('SAÍDAS-BASE'!J8="","",'SAÍDAS-BASE'!J8) | L10: =IF(TABELA_SAIDAS[[#This Row],[UF]]="","",IFERROR(IF(VLOOKUP(TABELA_SAIDAS[[#This Row],[VALOR]],TABELA_ENTRADAS[VALOR],1,FALSE),"DEVOLUÇÃO"),"SEM ENTRADAS"))
B11: =IF('SAÍDAS-BASE'!A9="","",'SAÍDAS-BASE'!A9) | C11: =IF('SAÍDAS-BASE'!B9="","",'SAÍDAS-BASE'!B9) | D11: =IF('SAÍDAS-BASE'!C9="","",'SAÍDAS-BASE'!C9) | E11: =IF('SAÍDAS-BASE'!D9="","",'SAÍDAS-BASE'!D9) | F11: =IF('SAÍDAS-BASE'!E9="","",'SAÍDAS-BASE'!E9) | G11: =IF('SAÍDAS-BASE'!F9="","",'SAÍDAS-BASE'!F9) | H11: =IF('SAÍDAS-BASE'!G9="","",'SAÍDAS-BASE'!G9) | I11: =IF('SAÍDAS-BASE'!H9="","",'SAÍDAS-BASE'!H9) | ... K11: =IF('SAÍDAS-BASE'!J9="","",'SAÍDAS-BASE'!J9) | L11: =IF(TABELA_SAIDAS[[#This Row],[UF]]="","",IFERROR(IF(VLOOKUP(TABELA_SAIDAS[[#This Row],[VALOR]],TABELA_ENTRADAS[VALOR],1,FALSE),"DEVOLUÇÃO"),"SEM ENTRADAS"))
B12: =IF('SAÍDAS-BASE'!A10="","",'SAÍDAS-BASE'!A10) | C12: =IF('SAÍDAS-BASE'!B10="","",'SAÍDAS-BASE'!B10) | D12: =IF('SAÍDAS-BASE'!C10="","",'SAÍDAS-BASE'!C10) | E12: =IF('SAÍDAS-BASE'!D10="","",'SAÍDAS-BASE'!D10) | F12: =IF('SAÍDAS-BASE'!E10="","",'SAÍDAS-BASE'!E10) | G12: =IF('SAÍDAS-BASE'!F10="","",'SAÍDAS-BASE'!F10) | H12: =IF('SAÍDAS-BASE'!G10="","",'SAÍDAS-BASE'!G10) | I12: =IF('SAÍDAS-BASE'!H10="","",'SAÍDAS-BASE'!H10) | ... K12: =IF('SAÍDAS-BASE'!J10="","",'SAÍDAS-BASE'!J10) | L12: =IF(TABELA_SAIDAS[[#This Row],[UF]]="","",IFERROR(IF(VLOOKUP(TABELA_SAIDAS[[#This Row],[VALOR]],TABELA_ENTRADAS[VALOR],1,FALSE),"DEVOLUÇÃO"),"SEM ENTRADAS"))
B13: =IF('SAÍDAS-BASE'!A11="","",'SAÍDAS-BASE'!A11) | C13: =IF('SAÍDAS-BASE'!B11="","",'SAÍDAS-BASE'!B11) | D13: =IF('SAÍDAS-BASE'!C11="","",'SAÍDAS-BASE'!C11) | E13: =IF('SAÍDAS-BASE'!D11="","",'SAÍDAS-BASE'!D11) | F13: =IF('SAÍDAS-BASE'!E11="","",'SAÍDAS-BASE'!E11) | G13: =IF('SAÍDAS-BASE'!F11="","",'SAÍDAS-BASE'!F11) | H13: =IF('SAÍDAS-BASE'!G11="","",'SAÍDAS-BASE'!G11) | I13: =IF('SAÍDAS-BASE'!H11="","",'SAÍDAS-BASE'!H11) | ... K13: =IF('SAÍDAS-BASE'!J11="","",'SAÍDAS-BASE'!J11) | L13: =IF(TABELA_SAIDAS[[#This Row],[UF]]="","",IFERROR(IF(VLOOKUP(TABELA_SAIDAS[[#This Row],[VALOR]],TABELA_ENTRADAS[VALOR],1,FALSE),"DEVOLUÇÃO"),"SEM ENTRADAS"))
B14: =IF('SAÍDAS-BASE'!A12="","",'SAÍDAS-BASE'!A12) | C14: =IF('SAÍDAS-BASE'!B12="","",'SAÍDAS-BASE'!B12) | D14: =IF('SAÍDAS-BASE'!C12="","",'SAÍDAS-BASE'!C12) | E14: =IF('SAÍDAS-BASE'!D12="","",'SAÍDAS-BASE'!D12) | F14: =IF('SAÍDAS-BASE'!E12="","",'SAÍDAS-BASE'!E12) | G14: =IF('SAÍDAS-BASE'!F12="","",'SAÍDAS-BASE'!F12) | H14: =IF('SAÍDAS-BASE'!G12="","",'SAÍDAS-BASE'!G12) | I14: =IF('SAÍDAS-BASE'!H12="","",'SAÍDAS-BASE'!H12) | ... K14: =IF('SAÍDAS-BASE'!J12="","",'SAÍDAS-BASE'!J12) | L14: =IF(TABELA_SAIDAS[[#This Row],[UF]]="","",IFERROR(IF(VLOOKUP(TABELA_SAIDAS[[#This Row],[VALOR]],TABELA_ENTRADAS[VALOR],1,FALSE),"DEVOLUÇÃO"),"SEM ENTRADAS"))
... B1000: =IF('SAÍDAS-BASE'!A998="","",'SAÍDAS-BASE'!A998) | C1000: =IF('SAÍDAS-BASE'!B998="","",'SAÍDAS-BASE'!B998) | D1000: =IF('SAÍDAS-BASE'!C998="","",'SAÍDAS-BASE'!C998) | E1000: =IF('SAÍDAS-BASE'!D998="","",'SAÍDAS-BASE'!D998) | F1000: =IF('SAÍDAS-BASE'!E998="","",'SAÍDAS-BASE'!E998) | G1000: =IF('SAÍDAS-BASE'!F998="","",'SAÍDAS-BASE'!F998) | H1000: =IF('SAÍDAS-BASE'!G998="","",'SAÍDAS-BASE'!G998) | I1000: =IF('SAÍDAS-BASE'!H998="","",'SAÍDAS-BASE'!H998) | ... K1000: =IF('SAÍDAS-BASE'!J998="","",'SAÍDAS-BASE'!J998) | L1000: =IF(TABELA_SAIDAS[[#This Row],[UF]]="","",IFERROR(IF(VLOOKUP(TABELA_SAIDAS[[#This Row],[VALOR]],TABELA_ENTRADAS[VALOR],1,FALSE),"DEVOLUÇÃO"),"SEM ENTRADAS"))

Sheet SAÍDAS-BASE
A1: {=_xlfn._xlws.FILTER(RELATORIO[[UF]:[VALOR]],RELATORIO[TIPO]="SAÍDA")} -> #VALUE!

Sheet SISTEMA-AUX
A1: Relação de Compras no Período (resumido)
A3: FORNECEDOR: - ***TODOS***
A4: TIPO: <<TODOS>>
A5: DEPOSITO: <<TODOS>> | C5: Por favor, alimente com os campos NF, Fornecedor e Vlr. Nota
A7: Entrada | B7: NF | C7: Fornecedor | D7: Desconto | E7: Vlr. Nota | F7: Valor Contas a Pagar | G7: Pedido | H7: Conferência | I7: Data Emissão
A8: =IF(SISTEMA!A2="","",SISTEMA!A2) | B8: =IF(SISTEMA!B2="","",VALUE(SISTEMA!B2)) | C8: =IF(SISTEMA!C2="","",SISTEMA!C2) | D8: {=IFERROR( _xlfn.XLOOKUP( --tabela_compras[[#This Row],[NF]], --INDEX(SISTEMA!$A$2:$Z$100000,0,MATCH("NF",SISTEMA!$A$1:$Z$1,0)), INDEX(SISTEMA!$A$2:$Z$100000,0,MATCH(tabela_compras[[#Headers],[Desconto]],SISTEMA!$A$1:$Z$1,0)) ), "" )} | E8: {=IFERROR( _xlfn.XLOOKUP( --tabela_compras[[#This Row],[NF]]&"|"&tabela_compras[[#This Row],[Fornecedor]], --INDEX(SISTEMA!$A$2:$Z$100000,0,MATCH("NF",SISTEMA!$A$1:$Z$1,0)) &"|"& INDEX(SISTEMA!$A$2:$Z$100000,0,MATCH("Fornecedor",SISTEMA!$A$1:$Z$1,0)), INDEX(SISTEMA!$A$2:$Z$100000,0,MATCH(tabela_compras[[#Headers],[Vlr. Nota]],SISTEMA!$A$1:$Z$1,0)) ), "" )} | F8: {=IFERROR( _xlfn.XLOOKUP( --tabela_compras[[#This Row],[NF]], --INDEX(SISTEMA!$A$2:$Z$100000,0,MATCH("NF",SISTEMA!$A$1:$Z$1,0)), INDEX(SISTEMA!$A$2:$Z$100000,0,MATCH(tabela_compras[[#Headers],[Valor Contas a Pagar]],SISTEMA!$A$1:$Z$1,0)) ), "" )} | G8: {=IFERROR( _xlfn.XLOOKUP( --tabela_compras[[#This Row],[NF]], --INDEX(SISTEMA!$A$2:$Z$100000,0,MATCH("NF",SISTEMA!$A$1:$Z$1,0)), INDEX(SISTEMA!$A$2:$Z$100000,0,MATCH(tabela_compras[[#Headers],[Pedido]],SISTEMA!$A$1:$Z$1,0)) ), "" )} | I8: {=IFERROR( _xlfn.XLOOKUP( --tabela_compras[[#This Row],[NF]], --INDEX(SISTEMA!$A$2:$Z$100000,0,MATCH("NF",SISTEMA!$A$1:$Z$1,0)), INDEX(SISTEMA!$A$2:$Z$100000,0,MATCH(tabela_compras[[#Headers],[Data Emissão]],SISTEMA!$A$1:$Z$1,0)) ), "" )}
A9: =IF(SISTEMA!A3="","",SISTEMA!A3) | B9: =IF(SISTEMA!B3="","",VALUE(SISTEMA!B3)) | C9: =IF(SISTEMA!C3="","",SISTEMA!C3) | D9: {=IFERROR( _xlfn.XLOOKUP( --tabela_compras[[#This Row],[NF]], --INDEX(SISTEMA!$A$2:$Z$100000,0,MATCH("NF",SISTEMA!$A$1:$Z$1,0)), INDEX(SISTEMA!$A$2:$Z$100000,0,MATCH(tabela_compras[[#Headers],[Desconto]],SISTEMA!$A$1:$Z$1,0)) ), "" )} | E9: {=IFERROR( _xlfn.XLOOKUP( --tabela_compras[[#This Row],[NF]]&"|"&tabela_compras[[#This Row],[Fornecedor]], --INDEX(SISTEMA!$A$2:$Z$100000,0,MATCH("NF",SISTEMA!$A$1:$Z$1,0)) &"|"& INDEX(SISTEMA!$A$2:$Z$100000,0,MATCH("Fornecedor",SISTEMA!$A$1:$Z$1,0)), INDEX(SISTEMA!$A$2:$Z$100000,0,MATCH(tabela_compras[[#Headers],[Vlr. Nota]],SISTEMA!$A$1:$Z$1,0)) ), "" )} | F9: {=IFERROR( _xlfn.XLOOKUP( --tabela_compras[[#This Row],[NF]], --INDEX(SISTEMA!$A$2:$Z$100000,0,MATCH("NF",SISTEMA!$A$1:$Z$1,0)), INDEX(SISTEMA!$A$2:$Z$100000,0,MATCH(tabela_compras[[#Headers],[Valor Contas a Pagar]],SISTEMA!$A$1:$Z$1,0)) ), "" )} | G9: {=IFERROR( _xlfn.XLOOKUP( --tabela_compras[[#This Row],[NF]], --INDEX(SISTEMA!$A$2:$Z$100000,0,MATCH("NF",SISTEMA!$A$1:$Z$1,0)), INDEX(SISTEMA!$A$2:$Z$100000,0,MATCH(tabela_compras[[#Headers],[Pedido]],SISTEMA!$A$1:$Z$1,0)) ), "" )} | I9: {=IFERROR( _xlfn.XLOOKUP( --tabela_compras[[#This Row],[NF]], --INDEX(SISTEMA!$A$2:$Z$100000,0,MATCH("NF",SISTEMA!$A$1:$Z$1,0)), INDEX(SISTEMA!$A$2:$Z$100000,0,MATCH(tabela_compras[[#Headers],[Data Emissão]],SISTEMA!$A$1:$Z$1,0)) ), "" )}
A10: =IF(SISTEMA!A4="","",SISTEMA!A4) | B10: =IF(SISTEMA!B4="","",VALUE(SISTEMA!B4)) | C10: =IF(SISTEMA!C4="","",SISTEMA!C4) | D10: {=IFERROR( _xlfn.XLOOKUP( --tabela_compras[[#This Row],[NF]], --INDEX(SISTEMA!$A$2:$Z$100000,0,MATCH("NF",SISTEMA!$A$1:$Z$1,0)), INDEX(SISTEMA!$A$2:$Z$100000,0,MATCH(tabela_compras[[#Headers],[Desconto]],SISTEMA!$A$1:$Z$1,0)) ), "" )} | E10: {=IFERROR( _xlfn.XLOOKUP( --tabela_compras[[#This Row],[NF]]&"|"&tabela_compras[[#This Row],[Fornecedor]], --INDEX(SISTEMA!$A$2:$Z$100000,0,MATCH("NF",SISTEMA!$A$1:$Z$1,0)) &"|"& INDEX(SISTEMA!$A$2:$Z$100000,0,MATCH("Fornecedor",SISTEMA!$A$1:$Z$1,0)), INDEX(SISTEMA!$A$2:$Z$100000,0,MATCH(tabela_compras[[#Headers],[Vlr. Nota]],SISTEMA!$A$1:$Z$1,0)) ), "" )} | F10: {=IFERROR( _xlfn.XLOOKUP( --tabela_compras[[#This Row],[NF]], --INDEX(SISTEMA!$A$2:$Z$100000,0,MATCH("NF",SISTEMA!$A$1:$Z$1,0)), INDEX(SISTEMA!$A$2:$Z$100000,0,MATCH(tabela_compras[[#Headers],[Valor Contas a Pagar]],SISTEMA!$A$1:$Z$1,0)) ), "" )} | G10: {=IFERROR( _xlfn.XLOOKUP( --tabela_compras[[#This Row],[NF]], --INDEX(SISTEMA!$A$2:$Z$100000,0,MATCH("NF",SISTEMA!$A$1:$Z$1,0)), INDEX(SISTEMA!$A$2:$Z$100000,0,MATCH(tabela_compras[[#Headers],[Pedido]],SISTEMA!$A$1:$Z$1,0)) ), "" )} | I10: {=IFERROR( _xlfn.XLOOKUP( --tabela_compras[[#This Row],[NF]], --INDEX(SISTEMA!$A$2:$Z$100000,0,MATCH("NF",SISTEMA!$A$1:$Z$1,0)), INDEX(SISTEMA!$A$2:$Z$100000,0,MATCH(tabela_compras[[#Headers],[Data Emissão]],SISTEMA!$A$1:$Z$1,0)) ), "" )}
A11: =IF(SISTEMA!A5="","",SISTEMA!A5) | B11: =IF(SISTEMA!B5="","",VALUE(SISTEMA!B5)) | C11: =IF(SISTEMA!C5="","",SISTEMA!C5) | D11: {=IFERROR( _xlfn.XLOOKUP( --tabela_compras[[#This Row],[NF]], --INDEX(SISTEMA!$A$2:$Z$100000,0,MATCH("NF",SISTEMA!$A$1:$Z$1,0)), INDEX(SISTEMA!$A$2:$Z$100000,0,MATCH(tabela_compras[[#Headers],[Desconto]],SISTEMA!$A$1:$Z$1,0)) ), "" )} | E11: {=IFERROR( _xlfn.XLOOKUP( --tabela_compras[[#This Row],[NF]]&"|"&tabela_compras[[#This Row],[Fornecedor]], --INDEX(SISTEMA!$A$2:$Z$100000,0,MATCH("NF",SISTEMA!$A$1:$Z$1,0)) &"|"& INDEX(SISTEMA!$A$2:$Z$100000,0,MATCH("Fornecedor",SISTEMA!$A$1:$Z$1,0)), INDEX(SISTEMA!$A$2:$Z$100000,0,MATCH(tabela_compras[[#Headers],[Vlr. Nota]],SISTEMA!$A$1:$Z$1,0)) ), "" )} | F11: {=IFERROR( _xlfn.XLOOKUP( --tabela_compras[[#This Row],[NF]], --INDEX(SISTEMA!$A$2:$Z$100000,0,MATCH("NF",SISTEMA!$A$1:$Z$1,0)), INDEX(SISTEMA!$A$2:$Z$100000,0,MATCH(tabela_compras[[#Headers],[Valor Contas a Pagar]],SISTEMA!$A$1:$Z$1,0)) ), "" )} | G11: {=IFERROR( _xlfn.XLOOKUP( --tabela_compras[[#This Row],[NF]], --INDEX(SISTEMA!$A$2:$Z$100000,0,MATCH("NF",SISTEMA!$A$1:$Z$1,0)), INDEX(SISTEMA!$A$2:$Z$100000,0,MATCH(tabela_compras[[#Headers],[Pedido]],SISTEMA!$A$1:$Z$1,0)) ), "" )} | I11: {=IFERROR( _xlfn.XLOOKUP( --tabela_compras[[#This Row],[NF]], --INDEX(SISTEMA!$A$2:$Z$100000,0,MATCH("NF",SISTEMA!$A$1:$Z$1,0)), INDEX(SISTEMA!$A$2:$Z$100000,0,MATCH(tabela_compras[[#Headers],[Data Emissão]],SISTEMA!$A$1:$Z$1,0)) ), "" )}
A12: =IF(SISTEMA!A6="","",SISTEMA!A6) | B12: =IF(SISTEMA!B6="","",VALUE(SISTEMA!B6)) | C12: =IF(SISTEMA!C6="","",SISTEMA!C6) | D12: {=IFERROR( _xlfn.XLOOKUP( --tabela_compras[[#This Row],[NF]], --INDEX(SISTEMA!$A$2:$Z$100000,0,MATCH("NF",SISTEMA!$A$1:$Z$1,0)), INDEX(SISTEMA!$A$2:$Z$100000,0,MATCH(tabela_compras[[#Headers],[Desconto]],SISTEMA!$A$1:$Z$1,0)) ), "" )} | E12: {=IFERROR( _xlfn.XLOOKUP( --tabela_compras[[#This Row],[NF]]&"|"&tabela_compras[[#This Row],[Fornecedor]], --INDEX(SISTEMA!$A$2:$Z$100000,0,MATCH("NF",SISTEMA!$A$1:$Z$1,0)) &"|"& INDEX(SISTEMA!$A$2:$Z$100000,0,MATCH("Fornecedor",SISTEMA!$A$1:$Z$1,0)), INDEX(SISTEMA!$A$2:$Z$100000,0,MATCH(tabela_compras[[#Headers],[Vlr. Nota]],SISTEMA!$A$1:$Z$1,0)) ), "" )} | F12: {=IFERROR( _xlfn.XLOOKUP( --tabela_compras[[#This Row],[NF]], --INDEX(SISTEMA!$A$2:$Z$100000,0,MATCH("NF",SISTEMA!$A$1:$Z$1,0)), INDEX(SISTEMA!$A$2:$Z$100000,0,MATCH(tabela_compras[[#Headers],[Valor Contas a Pagar]],SISTEMA!$A$1:$Z$1,0)) ), "" )} | G12: {=IFERROR( _xlfn.XLOOKUP( --tabela_compras[[#This Row],[NF]], --INDEX(SISTEMA!$A$2:$Z$100000,0,MATCH("NF",SISTEMA!$A$1:$Z$1,0)), INDEX(SISTEMA!$A$2:$Z$100000,0,MATCH(tabela_compras[[#Headers],[Pedido]],SISTEMA!$A$1:$Z$1,0)) ), "" )} | I12: {=IFERROR( _xlfn.XLOOKUP( --tabela_compras[[#This Row],[NF]], --INDEX(SISTEMA!$A$2:$Z$100000,0,MATCH("NF",SISTEMA!$A$1:$Z$1,0)), INDEX(SISTEMA!$A$2:$Z$100000,0,MATCH(tabela_compras[[#Headers],[Data Emissão]],SISTEMA!$A$1:$Z$1,0)) ), "" )}
A13: =IF(SISTEMA!A7="","",SISTEMA!A7) | B13: =IF(SISTEMA!B7="","",VALUE(SISTEMA!B7)) | C13: =IF(SISTEMA!C7="","",SISTEMA!C7) | D13: {=IFERROR( _xlfn.XLOOKUP( --tabela_compras[[#This Row],[NF]], --INDEX(SISTEMA!$A$2:$Z$100000,0,MATCH("NF",SISTEMA!$A$1:$Z$1,0)), INDEX(SISTEMA!$A$2:$Z$100000,0,MATCH(tabela_compras[[#Headers],[Desconto]],SISTEMA!$A$1:$Z$1,0)) ), "" )} | E13: {=IFERROR( _xlfn.XLOOKUP( --tabela_compras[[#This Row],[NF]]&"|"&tabela_compras[[#This Row],[Fornecedor]], --INDEX(SISTEMA!$A$2:$Z$100000,0,MATCH("NF",SISTEMA!$A$1:$Z$1,0)) &"|"& INDEX(SISTEMA!$A$2:$Z$100000,0,MATCH("Fornecedor",SISTEMA!$A$1:$Z$1,0)), INDEX(SISTEMA!$A$2:$Z$100000,0,MATCH(tabela_compras[[#Headers],[Vlr. Nota]],SISTEMA!$A$1:$Z$1,0)) ), "" )} | F13: {=IFERROR( _xlfn.XLOOKUP( --tabela_compras[[#This Row],[NF]], --INDEX(SISTEMA!$A$2:$Z$100000,0,MATCH("NF",SISTEMA!$A$1:$Z$1,0)), INDEX(SISTEMA!$A$2:$Z$100000,0,MATCH(tabela_compras[[#Headers],[Valor Contas a Pagar]],SISTEMA!$A$1:$Z$1,0)) ), "" )} | G13: {=IFERROR( _xlfn.XLOOKUP( --tabela_compras[[#This Row],[NF]], --INDEX(SISTEMA!$A$2:$Z$100000,0,MATCH("NF",SISTEMA!$A$1:$Z$1,0)), INDEX(SISTEMA!$A$2:$Z$100000,0,MATCH(tabela_compras[[#Headers],[Pedido]],SISTEMA!$A$1:$Z$1,0)) ), "" )} | I13: {=IFERROR( _xlfn.XLOOKUP( --tabela_compras[[#This Row],[NF]], --INDEX(SISTEMA!$A$2:$Z$100000,0,MATCH("NF",SISTEMA!$A$1:$Z$1,0)), INDEX(SISTEMA!$A$2:$Z$100000,0,MATCH(tabela_compras[[#Headers],[Data Emissão]],SISTEMA!$A$1:$Z$1,0)) ), "" )}
A14: =IF(SISTEMA!A8="","",SISTEMA!A8) | B14: =IF(SISTEMA!B8="","",VALUE(SISTEMA!B8)) | C14: =IF(SISTEMA!C8="","",SISTEMA!C8) | D14: {=IFERROR( _xlfn.XLOOKUP( --tabela_compras[[#This Row],[NF]], --INDEX(SISTEMA!$A$2:$Z$100000,0,MATCH("NF",SISTEMA!$A$1:$Z$1,0)), INDEX(SISTEMA!$A$2:$Z$100000,0,MATCH(tabela_compras[[#Headers],[Desconto]],SISTEMA!$A$1:$Z$1,0)) ), "" )} | E14: {=IFERROR( _xlfn.XLOOKUP( --tabela_compras[[#This Row],[NF]]&"|"&tabela_compras[[#This Row],[Fornecedor]], --INDEX(SISTEMA!$A$2:$Z$100000,0,MATCH("NF",SISTEMA!$A$1:$Z$1,0)) &"|"& INDEX(SISTEMA!$A$2:$Z$100000,0,MATCH("Fornecedor",SISTEMA!$A$1:$Z$1,0)), INDEX(SISTEMA!$A$2:$Z$100000,0,MATCH(tabela_compras[[#Headers],[Vlr. Nota]],SISTEMA!$A$1:$Z$1,0)) ), "" )} | F14: {=IFERROR( _xlfn.XLOOKUP( --tabela_compras[[#This Row],[NF]], --INDEX(SISTEMA!$A$2:$Z$100000,0,MATCH("NF",SISTEMA!$A$1:$Z$1,0)), INDEX(SISTEMA!$A$2:$Z$100000,0,MATCH(tabela_compras[[#Headers],[Valor Contas a Pagar]],SISTEMA!$A$1:$Z$1,0)) ), "" )} | G14: {=IFERROR( _xlfn.XLOOKUP( --tabela_compras[[#This Row],[NF]], --INDEX(SISTEMA!$A$2:$Z$100000,0,MATCH("NF",SISTEMA!$A$1:$Z$1,0)), INDEX(SISTEMA!$A$2:$Z$100000,0,MATCH(tabela_compras[[#Headers],[Pedido]],SISTEMA!$A$1:$Z$1,0)) ), "" )} | I14: {=IFERROR( _xlfn.XLOOKUP( --tabela_compras[[#This Row],[NF]], --INDEX(SISTEMA!$A$2:$Z$100000,0,MATCH("NF",SISTEMA!$A$1:$Z$1,0)), INDEX(SISTEMA!$A$2:$Z$100000,0,MATCH(tabela_compras[[#Headers],[Data Emissão]],SISTEMA!$A$1:$Z$1,0)) ), "" )}
A15: =IF(SISTEMA!A9="","",SISTEMA!A9) | B15: =IF(SISTEMA!B9="","",VALUE(SISTEMA!B9)) | C15: =IF(SISTEMA!C9="","",SISTEMA!C9) | D15: {=IFERROR( _xlfn.XLOOKUP( --tabela_compras[[#This Row],[NF]], --INDEX(SISTEMA!$A$2:$Z$100000,0,MATCH("NF",SISTEMA!$A$1:$Z$1,0)), INDEX(SISTEMA!$A$2:$Z$100000,0,MATCH(tabela_compras[[#Headers],[Desconto]],SISTEMA!$A$1:$Z$1,0)) ), "" )} | E15: {=IFERROR( _xlfn.XLOOKUP( --tabela_compras[[#This Row],[NF]]&"|"&tabela_compras[[#This Row],[Fornecedor]], --INDEX(SISTEMA!$A$2:$Z$100000,0,MATCH("NF",SISTEMA!$A$1:$Z$1,0)) &"|"& INDEX(SISTEMA!$A$2:$Z$100000,0,MATCH("Fornecedor",SISTEMA!$A$1:$Z$1,0)), INDEX(SISTEMA!$A$2:$Z$100000,0,MATCH(tabela_compras[[#Headers],[Vlr. Nota]],SISTEMA!$A$1:$Z$1,0)) ), "" )} | F15: {=IFERROR( _xlfn.XLOOKUP( --tabela_compras[[#This Row],[NF]], --INDEX(SISTEMA!$A$2:$Z$100000,0,MATCH("NF",SISTEMA!$A$1:$Z$1,0)), INDEX(SISTEMA!$A$2:$Z$100000,0,MATCH(tabela_compras[[#Headers],[Valor Contas a Pagar]],SISTEMA!$A$1:$Z$1,0)) ), "" )} | G15: {=IFERROR( _xlfn.XLOOKUP( --tabela_compras[[#This Row],[NF]], --INDEX(SISTEMA!$A$2:$Z$100000,0,MATCH("NF",SISTEMA!$A$1:$Z$1,0)), INDEX(SISTEMA!$A$2:$Z$100000,0,MATCH(tabela_compras[[#Headers],[Pedido]],SISTEMA!$A$1:$Z$1,0)) ), "" )} | I15: {=IFERROR( _xlfn.XLOOKUP( --tabela_compras[[#This Row],[NF]], --INDEX(SISTEMA!$A$2:$Z$100000,0,MATCH("NF",SISTEMA!$A$1:$Z$1,0)), INDEX(SISTEMA!$A$2:$Z$100000,0,MATCH(tabela_compras[[#Headers],[Data Emissão]],SISTEMA!$A$1:$Z$1,0)) ), "" )}
A16: =IF(SISTEMA!A10="","",SISTEMA!A10) | B16: =IF(SISTEMA!B10="","",VALUE(SISTEMA!B10)) | C16: =IF(SISTEMA!C10="","",SISTEMA!C10) | D16: {=IFERROR( _xlfn.XLOOKUP( --tabela_compras[[#This Row],[NF]], --INDEX(SISTEMA!$A$2:$Z$100000,0,MATCH("NF",SISTEMA!$A$1:$Z$1,0)), INDEX(SISTEMA!$A$2:$Z$100000,0,MATCH(tabela_compras[[#Headers],[Desconto]],SISTEMA!$A$1:$Z$1,0)) ), "" )} | E16: {=IFERROR( _xlfn.XLOOKUP( --tabela_compras[[#This Row],[NF]]&"|"&tabela_compras[[#This Row],[Fornecedor]], --INDEX(SISTEMA!$A$2:$Z$100000,0,MATCH("NF",SISTEMA!$A$1:$Z$1,0)) &"|"& INDEX(SISTEMA!$A$2:$Z$100000,0,MATCH("Fornecedor",SISTEMA!$A$1:$Z$1,0)), INDEX(SISTEMA!$A$2:$Z$100000,0,MATCH(tabela_compras[[#Headers],[Vlr. Nota]],SISTEMA!$A$1:$Z$1,0)) ), "" )} | F16: {=IFERROR( _xlfn.XLOOKUP( --tabela_compras[[#This Row],[NF]], --INDEX(SISTEMA!$A$2:$Z$100000,0,MATCH("NF",SISTEMA!$A$1:$Z$1,0)), INDEX(SISTEMA!$A$2:$Z$100000,0,MATCH(tabela_compras[[#Headers],[Valor Contas a Pagar]],SISTEMA!$A$1:$Z$1,0)) ), "" )} | G16: {=IFERROR( _xlfn.XLOOKUP( --tabela_compras[[#This Row],[NF]], --INDEX(SISTEMA!$A$2:$Z$100000,0,MATCH("NF",SISTEMA!$A$1:$Z$1,0)), INDEX(SISTEMA!$A$2:$Z$100000,0,MATCH(tabela_compras[[#Headers],[Pedido]],SISTEMA!$A$1:$Z$1,0)) ), "" )} | I16: {=IFERROR( _xlfn.XLOOKUP( --tabela_compras[[#This Row],[NF]], --INDEX(SISTEMA!$A$2:$Z$100000,0,MATCH("NF",SISTEMA!$A$1:$Z$1,0)), INDEX(SISTEMA!$A$2:$Z$100000,0,MATCH(tabela_compras[[#Headers],[Data Emissão]],SISTEMA!$A$1:$Z$1,0)) ), "" )}
A17: =IF(SISTEMA!A11="","",SISTEMA!A11) | B17: =IF(SISTEMA!B11="","",VALUE(SISTEMA!B11)) | C17: =IF(SISTEMA!C11="","",SISTEMA!C11) | D17: {=IFERROR( _xlfn.XLOOKUP( --tabela_compras[[#This Row],[NF]], --INDEX(SISTEMA!$A$2:$Z$100000,0,MATCH("NF",SISTEMA!$A$1:$Z$1,0)), INDEX(SISTEMA!$A$2:$Z$100000,0,MATCH(tabela_compras[[#Headers],[Desconto]],SISTEMA!$A$1:$Z$1,0)) ), "" )} | E17: {=IFERROR( _xlfn.XLOOKUP( --tabela_compras[[#This Row],[NF]]&"|"&tabela_compras[[#This Row],[Fornecedor]], --INDEX(SISTEMA!$A$2:$Z$100000,0,MATCH("NF",SISTEMA!$A$1:$Z$1,0)) &"|"& INDEX(SISTEMA!$A$2:$Z$100000,0,MATCH("Fornecedor",SISTEMA!$A$1:$Z$1,0)), INDEX(SISTEMA!$A$2:$Z$100000,0,MATCH(tabela_compras[[#Headers],[Vlr. Nota]],SISTEMA!$A$1:$Z$1,0)) ), "" )} | F17: {=IFERROR( _xlfn.XLOOKUP( --tabela_compras[[#This Row],[NF]], --INDEX(SISTEMA!$A$2:$Z$100000,0,MATCH("NF",SISTEMA!$A$1:$Z$1,0)), INDEX(SISTEMA!$A$2:$Z$100000,0,MATCH(tabela_compras[[#Headers],[Valor Contas a Pagar]],SISTEMA!$A$1:$Z$1,0)) ), "" )} | G17: {=IFERROR( _xlfn.XLOOKUP( --tabela_compras[[#This Row],[NF]], --INDEX(SISTEMA!$A$2:$Z$100000,0,MATCH("NF",SISTEMA!$A$1:$Z$1,0)), INDEX(SISTEMA!$A$2:$Z$100000,0,MATCH(tabela_compras[[#Headers],[Pedido]],SISTEMA!$A$1:$Z$1,0)) ), "" )} | I17: {=IFERROR( _xlfn.XLOOKUP( --tabela_compras[[#This Row],[NF]], --INDEX(SISTEMA!$A$2:$Z$100000,0,MATCH("NF",SISTEMA!$A$1:$Z$1,0)), INDEX(SISTEMA!$A$2:$Z$100000,0,MATCH(tabela_compras[[#Headers],[Data Emissão]],SISTEMA!$A$1:$Z$1,0)) ), "" )}
